Workbook
Name _10._PITS: '[1]10. Pits'!$C$2
Name _11_UNDERGROUND_MINES: '[1]11.Underground Mines'!$C$2
Name _12._PORTS: '[1]12. Ports'!$C$2
Name _13._INVESTIGATION_CONTAMINATION_SCRAP_LEVY: '[1]13. Investigation Contamination'!$C$2
Name _14._GENERAL_LAND_REHABILITATION: '[1]14. General Land Rehabilitation'!$C$2
Name _15._MOBILISATION___DEMOBILISATION_AND_ADDITIONAL_USER_ITEMS: '[1]15. Mobilisation and User'!$C$2
Name _2._EXPLORATION: '[1]2. Exploration'!$C$2
Name _3._INFRASTRUCTURE: '[1]3. Infrastructure'!$C$2
Name _5._WATER_STORAGE: '[1]5. Water Storage'!$C$2
Name _6._WATER_TREATMENT_AND_PUMPING: '[1]6. Water Treatment'!$C$2
Name _7._WASTE_ROCK_DUMPS__OVERBURDEN_DUMPS__SPOIL_PILES_AND_STOCKPILES: '[1]7. Overburden Dumps Piles'!$C$2
Name _8._HEAP_LEACH_PADS: '[1]8. Heap Leach Pads'!$C$2
Name _9._TAILING_STORAGE_FACILITIES__REJECTS__SLIMES__SLIMES_STORAGE_FACILITIES: '[1]9. Tailings Storage Facilities'!$C$2
Name Building_list: [1]Lists!$B$190:$B$195
Name Cost_Schedule: '2024 Cost Schedule for Tool'!$C$10:$F$296
Name Cost_Schedule: #REF!
Name ELIGIBLE_MINING_ACTIVITIES: '[1]1. Eligible Mining Activities'!$C$2
Name Select_Haul_Dist_315: [2]System!$A$27:$A$30
Name Select_Haul_Dist_315_Index: [2]System!$A$27:$B$30
Name Select_Haul_Dist_805_Index: [2]System!$A$32:$B$35
Name Select_Haul_Distance: [2]System!$A$3:$A$7
Name Select_Haul_Distance_Here: [2]System!$A$22:$A$25
Name Select_Haul_distance_Here_index: [2]System!$A$22:$B$25
Name Select_Haul_Distance_Index: [2]System!$A$3:$B$7
Name Select_HAZMAT: [2]System!$A$38:$A$41
Name Select_HAZMAT_Index: [2]System!$A$38:$B$41
Name Select_Op: [2]System!#REF!
Name Select_Push_Length: [2]System!$A$9:$A$13
Name Select_Push_Length_Index: [2]System!$A$9:$B$13
Name Select_Volume: [2]System!$A$15:$A$19
Name Select_Volume_Index: [2]System!$A$15:$B$19
Name Total_Liability: #REF!

Sheet High Level Summary
A1: Item Number | B1: Estimated Cost 2024 Triennial Review
A2: Domain 1 - Surface Infrastructure | B2: 74443158
A3: Domain 2 - Tailings and Reject Emplacement Areas | B3: 1.2640301e+08
A4: Domain 3 - Overburden / Waste Emplacement Areas | B4: 26410704
A5: Domain 4 - Active Mining, Pits and Voids | B5: 2.1653769e+08
A6: Domain 5 - Water Management | B6: 5720137.5
A7: Domain 6 - Existing Rehabilitation Areas | B7: 23229568
A8: Domain 7 - Offset Areas | B8: 0
A9: Domain 8 - Underground Mining Areas | B9: 18102520
A10: Domain 9 - Other Lands | B10: 1137592
A11: Whole of Site - Sundry Items and HR/Admin/Stakeholders | B11: 2130821.3
A12: Contingencies etc | B12: 1.7294032e+08
A13: Holding Costs | B13: 2.3294449e+08
A14: Total | B14: =SUM(B2:B13) -> 900000000

Sheet Planned Closure Detail
A1: Springbok Creek | B1: Planned Closure Costing (2024) | F1: Total Liability | G1: 45536
G2: =G474 -> 9e+08
A5: Item Number | B5: Activity / Description | C5: 2024 Quantity | D5: Unit | E5: Cost code | F5: 2024 Unit Rate | G5: Estimated Cost 2024 Triennial Review | H5: 2024 Comments
A6: Domain 1 - Surface Infrastructure | G6: =SUM(G7,G19,G25,G29,G46,G54,G57,G108,G60,G71,G84,G93,G102) -> 74443158
A7: Domain 1A - MIA (Admin, workshops, bathhouse, car park etc) | G7: =SUM(G8,G14,G16) -> 5591103.5
A8: Termination of Services and Demolition Works | G8: =SUM(G9:G13) -> 4487897.3
A9: 1.001 | B9: Disconnect and terminate all services (Water, electricity, gas etc. at point of attachment to site). | C9: 1 | D9: @ | E9: 1.01 | F9: =VLOOKUP(E9,'2024 Cost Schedule for Tool'!$C$9:$F$299,4,0) -> 47518.457 | G9: =IF(D9="",0,C9*F9) -> 47518.457 | H9: No change in quantity in 2024 review. A provisional amount used to allow for the removal of services.
A10: 1.002 | B10: Demolish and remove small buildings/tanks (admin buildings - single story etc). | C10: 12531.099 | D10: m2 | E10: 1.09 | F10: =VLOOKUP(E10,'2024 Cost Schedule for Tool'!$C$9:$F$299,4,0) -> 91.359913 | G10: =IF(D10="",0,C10*F10) -> 1144840.1 | H10: No change in quantity in 2024 review.
A11: 1.003 | B11: Remove concrete pads and footings (< 0.3 m thickness) from small buildings and dumping in void. | C11: 13784.209 | D11: m2 | E11: 1.43 | F11: =VLOOKUP(E11,'2024 Cost Schedule for Tool'!$C$9:$F$299,4,0) -> 41.116034 | G11: =IF(D11="",0,C11*F11) -> 566752.01 | H11: No change in quantity in 2024 review. Estimate includes additional 10% for aprons, pathways etc.
A12: 1.004 | B12: Demolish and remove medium buildings | C12: 14731.545 | D12: m2/level | E12: 1.1 | F12: =VLOOKUP(E12,'2024 Cost Schedule for Tool'!$C$9:$F$299,4,0) -> 92.297865 | G12: =IF(D12="",0,C12*F12) -> 1359690.2 | H12: No change in quantity in 2024 review. Areas calculated for medium buildings in domain.
A13: 1.005 | B13: Remove concrete pads and footings (> 0.3 m thickness) from medium buildings and dumping in void. | C13: 16205.202 | D13: m2 | E13: 1.44 | F13: =VLOOKUP(E13,'2024 Cost Schedule for Tool'!$C$9:$F$299,4,0) -> 84.485002 | G13: =IF(D13="",0,C13*F13) -> 1369096.5 | H13: No change in quantity in 2024 review. Estimate includes additional 10% for aprons, pathways etc.
A14: Minor Reshaping, Final Trim (Roads) | C14: 0 | G14: =SUM(G15) -> 982125.65
A15: 1.006 | B15: Remove hardstand material (spillage or otherwise) from footprint of Domain (Does not include product stockpiles, CHPP or ROM) (haul distance > 1 km but < 2 km). | C15: 171335.15 | D15: m3 | E15: 3.08 | F15: =VLOOKUP(E15,'2024 Cost Schedule for Tool'!$C$9:$F$299,4,0) -> 5.7321901 | G15: =IF(D15="",0,C15*F15) -> 982125.65 | H15: No change in quantity in 2024 review. Assume 0.3 m depth hardstand material removed.
A16: Contaminated materials | C16: 0 | G16: =SUM(G17:G18) -> 121080.53
A17: 1.007 | B17: Onsite remediation of hydrocarbon contaminated soils (>1000m3) | C17: 1003.8532 | D17: m3 | E17: 4.12 | F17: =VLOOKUP(E17,'2024 Cost Schedule for Tool'!$C$9:$F$299,4,0) -> 84.485002 | G17: =IF(D17="",0,C17*F17) -> 84810.537 | H17: No change in quantity in 2024 review. Provisional sum.
A18: 1.008 | B18: Construct and set up bioremediation pad | C18: 0.933296 | D18: allow | E18: 4.09a | F18: =VLOOKUP(E18,'2024 Cost Schedule for Tool'!$C$9:$F$299,4,0) -> 38862.259 | G18: =IF(D18="",0,C18*F18) -> 36269.991 | H18: No change in quantity in 2024 review.
A19: Domain 1B - CHPP Main Plant | C19: 0 | G19: =SUM(G20:G24) -> 17123864
A20: Termination of Services and Demolition Works | C20: 0 | G20: =SUM(G22:G24) -> 0
A21: 1.009 | B21: Demolish and remove CHPP | C21: 0.933296 | D21: @ | E21: SS | F21: =15768913+2578818 -> 18347731 | G21: =IF(D21="",0,C21*F21) -> 17123864
A22: 1.01 | B22: Demolish and remove CHPP (include the area of each floor of the structure) | C22: 0 | D22: m2/level | E22: 1.12 | F22: =VLOOKUP(E22,'2024 Cost Schedule for Tool'!$C$9:$F$299,4,0) -> 247.82643 | G22: =IF(D22="",0,C22*F22) -> 0 | H22: Captured above
A23: 1.011 | B23: Demolish and remove heavy industrial buildings - crushers, sizing stations, rotary breakers, etc (area of each floor of the structure). | C23: 0 | D23: m2/level | E23: 1.13 | F23: =VLOOKUP(E23,'2024 Cost Schedule for Tool'!$C$9:$F$299,4,0) -> 253.455 | G23: =IF(D23="",0,C23*F23) -> 0 | H23: Captured above
A24: 1.012 | B24: Remove concrete pads and footings (> 0.3 m thickness) and dumping in void. | C24: 0 | D24: m2 | E24: 1.44 | F24: =VLOOKUP(E24,'2024 Cost Schedule for Tool'!$C$9:$F$299,4,0) -> 84.485002 | G24: =IF(D24="",0,C24*F24) -> 0 | H24: Captured above
A25: Domain 1C - CHPP MOD 4 | C25: 0 | G25: =SUM(G26) -> 838423.35
A26: Termination of Services and Demolition Works | C26: 0 | G26: =SUM(G27:G28) -> 838423.35
A27: 1.013 | B27: Demolish and remove CHPP (include the area of each floor of the structure) | C27: 3147.0797 | D27: m2/level | E27: 1.12 | F27: =VLOOKUP(E27,'2024 Cost Schedule for Tool'!$C$9:$F$299,4,0) -> 247.82643 | G27: =IF(D27="",0,C27*F27) -> 779929.52 | H27: No change in quantity in 2024 review. ~627 m2 x 5 levels.
A28: 1.014 | B28: Remove concrete pads and footings (> 300 mm thickness) and dumping in void. | C28: 692.35754 | D28: m2 | E28: 1.44 | F28: =VLOOKUP(E28,'2024 Cost Schedule for Tool'!$C$9:$F$299,4,0) -> 84.485002 | G28: =IF(D28="",0,C28*F28) -> 58493.828 | H28: No change in quantity in 2024 review. Estimate includes additional 10% for aprons, pathways etc.
A29: Domain 1D - Product Stockpiles and ROM (includes relevant Rail Loop infrastructure) | C29: 0 | G29: =SUM(G30,G39,G41,G43) -> 13036272
A30: Termination of Services and Demolition Works | C30: 0 | G30: =SUM(G31:G38) -> 11698302
A31: 1.015 | B31: Demolish and remove bucket wheel stacker/reclaimer | C31: 3.733184 | D31: @ | E31: 1.15 | F31: =VLOOKUP(E31,'2024 Cost Schedule for Tool'!$C$9:$F$299,4,0) -> 2252933.4 | G31: =IF(D31="",0,C31*F31) -> 8410614.8 | H31: No change in quantity in 2024 review. Just removal of the bucket wheel stacker/reclaim unit - does not include terminate services, remove rails and ballast etc.
A32: 1.016 | B32: Demolish and remove on ground conveyors, transfer stations & gantries (scrap only – does not include dismantling for reuse at another site). | C32: 6392.8681 | D32: m | E32: 1.21 | F32: =VLOOKUP(E32,'2024 Cost Schedule for Tool'!$C$9:$F$299,4,0) -> 225.64273 | G32: =IF(D32="",0,C32*F32) -> 1442504.2 | H32: No change in quantity in 2024 review. All within the CHPP/stockpile area.
A33: 1.017 | B33: Demolish and remove elevated conveyors, transfer stations & gantries (scrap only – does not include dismantling for reuse at another site). | C33: 355.15934 | D33: m | E33: 1.22 | F33: =VLOOKUP(E33,'2024 Cost Schedule for Tool'!$C$9:$F$299,4,0) -> 463.05751 | G33: =IF(D33="",0,C33*F33) -> 164459.2 | H33: No change in quantity in 2024 review. All within the CHPP/stockpile area.
A34: 1.018 | B34: Demolish and remove overhead conveyors, transfer stations & gantries (scrap only – does not include dismantling for reuse at another site) | C34: 355.15934 | D34: m | E34: 1.23 | F34: =VLOOKUP(E34,'2024 Cost Schedule for Tool'!$C$9:$F$299,4,0) -> 957.49669 | G34: =IF(D34="",0,C34*F34) -> 340063.89 | H34: No change in quantity in 2024 review. All within the CHPP/stockpile area.
A35: 1.019 | B35: Demolish reclaim tunnel, cut reo and expose reclaim conveyor, then collapse into the reclaim tunnel void (Does not include excavation to expose reclaim tunnel, removal of conveyor or backfilling void). | C35: 11293.348 | D35: m2 | E35: 1.24 | F35: =VLOOKUP(E35,'2024 Cost Schedule for Tool'!$C$9:$F$299,4,0) -> 107.01434 | G35: =IF(D35="",0,C35*F35) -> 1208550.2 | H35: No change in quantity in 2024 review.
A36: 1.02 | B36: Remove and demolish conveyor from reclaim tunnel (Does not include excavation and demolition of reclaim tunnel roof). | C36: 150.57798 | D36: m | E36: 1.25 | F36: =VLOOKUP(E36,'2024 Cost Schedule for Tool'!$C$9:$F$299,4,0) -> 168.97 | G36: =IF(D36="",0,C36*F36) -> 25443.161 | H36: No change in quantity in 2024 review. Estimate for underground conveyor infrastructure to be removed.
A37: 1.021 | B37: Remove concrete pads and footings (> 300 mm thickness) and dumping in void. | C37: 401.54127 | D37: m2 | E37: 1.44 | F37: =VLOOKUP(E37,'2024 Cost Schedule for Tool'!$C$9:$F$299,4,0) -> 84.485002 | G37: =IF(D37="",0,C37*F37) -> 33924.215 | H37: No change in quantity in 2024 review. Assume ~0.5 m footings.
A38: 1.022 | B38: Demolish and remove rejects bin | C38: 0.933296 | D38: @ | E38: 1.19 | F38: =VLOOKUP(E38,'2024 Cost Schedule for Tool'!$C$9:$F$299,4,0) -> 77940.938 | G38: =IF(D38="",0,C38*F38) -> 72741.965 | H38: No change in quantity in 2024 review. Assumes 1250 t coal bin.
A39: Minor Reshaping, Final Trim (Roads) | C39: 0 | G39: =SUM(G40) -> 0
A40: 1.023 | B40: Unsealed roads / vehicle park-up areas – Minor earthworks, final trim and deep rip and seed (pasture grass) | C40: 0 | D40: ha | E40: 3.03 | F40: =VLOOKUP(E40,'2024 Cost Schedule for Tool'!$C$9:$F$299,4,0) -> 3723.4649 | G40: =IF(D40="",0,C40*F40) -> 0 | H40: Zeroed as these are now consolidated at the bottom of the infrastructure domain.
A41: Contaminated materials | C41: 0 | G41: =SUM(G42) -> 1327472.7
A42: 1.024 | B42: Remove carbonaceous material (spillage or otherwise) from footprint of the CHPP, ROM, Product stockpiles & Roadways (haul distance > 1 km but < 2 km). | C42: 231739.51 | D42: m3 | E42: 4.04 | F42: =VLOOKUP(E42,'2024 Cost Schedule for Tool'!$C$9:$F$299,4,0) -> 5.728297 | G42: =IF(D42="",0,C42*F42) -> 1327472.7 | H42: No change in quantity in 2024 review. Includes scalping carbonaceous material from ROM and two product stockpile areas to depth of 0.5 m.
...

Sheet BulkPush
B3: Planned Closure Cost Volumes and Push Lengths Required:
B4: Equipment (Dozer) | C4: Planned closure (Active Mining, Pits and Voids): | D4: 2024 Volume (m3) | S4: Planned Closure Volume (m3) | Y4: Comments
D5: P1 | E5: P2 | F5: P3 | G5: P4 | H5: P5 | I5: P6 | J5: G6 | K5: A3 | L5: A4 | M5: G8 | N5: G5 | O5: G3 | P5: G4 | Q5: G7 | R5: G9 | S5: Pit 1 (insert pit name) | T5: Pit 2 | U5: Pit 3 | V5: Pit 4 | W5: Pit 5 | X5: Total
B6: Benches, high wall treatment | C6: Active pit area – benches blasted and doze to acceptable grade | X6: =SUM(S6:W6) -> 0
C7: Drill & blast faces to make safe | X7: =SUM(S7:W7) -> 0
C8: High wall treatment – (trench and safety berm) no additional works required to establish | X8: =SUM(S8:W8) -> 0
C9: High wall treatment – (trench and safety berm) with additional treatment of adjacent loose weathered material | X9: =SUM(S9:W9) -> 0
B10: D10 Major bulk | C10: 50m push length. | X10: =SUM(S10:W10) -> 0
C11: 50m-100m push length | X11: =SUM(S11:W11) -> 0
C12: 100m-150m push length | X12: =SUM(S12:W12) -> 0
C13: 150m - 200 m push length | X13: =SUM(S13:W13) -> 0
C14: 200m - 300 m push length | X14: =SUM(S14:W14) -> 0
C15: >300 m push length | S15: Use load and haul for distances greater than 300m. | X15: =SUM(S15:W15) -> 0
B16: D11 Major bulk | C16: 50m push length. | X16: =SUM(S16:W16) -> 0
C17: 50m-100m push length | X17: =SUM(S17:W17) -> 0
C18: 100m-150m push length | D18: 11495082 | E18: 1099857.5 | F18: 12027602 | G18: 6976693.1 | H18: 3614573.6 | I18: 1394252.8 | J18: 2834489.9 | K18: 4594261.9 | L18: 2708791.9 | M18: 2331697.9 | N18: 2080301.9 | O18: 1577509.9 | P18: 1577509.9 | Q18: 3588677.9 | R18: 1074717.9 | X18: =SUM(D18:W18) -> 58976020
C19: 150m - 200 m push length | X19: =SUM(S19:W19) -> 0
C20: 200m - 300 m push length | X20: =SUM(S20:W20) -> 0
C21: >300 m push length | S21: Use load and haul for distances greater than 300m. | X21: =SUM(S21:W21) -> 0
B23: Equipment (Dozer) | C23: Planned closure (Overburden/Waste Emplacement Areas): | S23: Planned Closure Volume (m3) | Y23: Comments
S24: Dump 1 (insert dump name | T24: Dump 2 | U24: Dump 3 | V24: Dump 4 | W24: Dump 5 | X24: Total
B25: D10 Major bulk | C25: 50m push length. | X25: =SUM(S25:W25) -> 0
C26: 50m-100m push length | X26: =SUM(S26:W26) -> 0
C27: 100m-150m push length | X27: =SUM(S27:W27) -> 0
C28: 150m - 200 m push length | X28: =SUM(S28:W28) -> 0
C29: 200m - 300 m push length | X29: =SUM(S29:W29) -> 0
C30: >300 m push length | S30: Use load and haul for distances greater than 300m. | X30: =SUM(S30:W30) -> 0
B31: D11 Major bulk | C31: 50m push length. | X31: =SUM(S31:W31) -> 0
C32: 50m-100m push length | X32: =SUM(S32:W32) -> 0
C33: 100m-150m push length | X33: =SUM(S33:W33) -> 0
C34: 150m - 200 m push length | X34: =SUM(S34:W34) -> 0
C35: 200m - 300 m push length | X35: =SUM(S35:W35) -> 0
C36: >300 m push length | S36: Use load and haul for distances greater than 300m. | X36: =SUM(S36:W36) -> 0
B38: Equipment (Dozer) | C38: Planned closure (Tailings Dams): Assuming material that is placed on the approved cap. Ie. Material to get to final landform, after capping. | S38: Planned Closure Volume (m3) | Y38: Comments
S39: Tailings Dam 1 (insert TD name | T39: Tailings Dam 2 (insert TD name | U39: Tailings Dam 3 (insert TD name | V39: Tailings Dam 4 (insert TD name | W39: Tailings Dam 5 (insert TD name | X39: Total
B40: D10 Major bulk | C40: 50m push length. | X40: =SUM(S40:W40) -> 0
C41: 50m-100m push length | X41: =SUM(S41:W41) -> 0
C42: 100m-150m push length | X42: =SUM(S42:W42) -> 0
C43: 150m - 200 m push length | X43: =SUM(S43:W43) -> 0
C44: 200m - 300 m push length | X44: =SUM(S44:W44) -> 0
...

Sheet Haulage
B1: Imminent Closure - Volumes and Load and Haul Lengths Required: | AF1: Planned Closure - Volumes and Load and Haul Lengths Required:
B2: Imminent closure: | C2: =+AG2 -> P1 | D2: =+AH2 -> P2 | E2: =+AI2 -> P3 | F2: =+AJ2 -> P4 | G2: =+AK2 -> P5 | H2: =+AL2 -> P6 | I2: =+AM2 -> W6 | J2: =+AN2 -> A3 | ... W2: =+BA2 -> 0 | X2: Haul 1 (m3) | Y2: Haul 2 (m3) | Z2: Haul 3 (m3) | AA2: Total (m3) | AB2: Comments | AF2: Planned closure: | AG2: P1 | AH2: P2 | AI2: P3 | AJ2: P4 | AK2: P5 | AL2: P6 | AM2: W6 | AN2: A3 | AO2: A4 | AP2: W8 | AQ2: W5 | AR2: W3 | AS2: W4 | AT2: W7 | AU2: W9 | AV2: Total (m3) | AW2: Comments
B3: 800t fleet - Flat | AF3: 100t fleet - Flat
B4: Load and haul 800 t fleet, flat, <1km | D4: =+AH4 -> 568569.88 | E4: =+AI4 -> 5812126.5 | F4: =+AJ4 -> 1116340 | G4: =+AK4 -> 1372948.5 | H4: =+AL4 -> 3843896 | AA4: =SUM(C4:Z4) -> 12713881 | AF4: Load and haul 100 t fleet, flat, <1km | AG4: 1638064.1 | AH4: 568569.88 | AI4: 5812126.5 | AJ4: 1116340 | AK4: 1372948.5 | AL4: 3843896 | AV4: =SUM(AG4:AU4) -> 14351945
B5: Load and haul 800 t fleet, flat, 1-2km | J5: 300000 | K5: 400000 | L5: 500000 | M5: 400000 | O5: 100000 | Q5: 100000 | AA5: =SUM(C5:Z5) -> 1800000 | AB5: See the conceptual option4 | AF5: Load and haul 100 t fleet, flat, 1-2km | AM5: 835943.44 | AN5: 434883.1 | AO5: 568569.88 | AP5: 702256.66 | AQ5: 568569.88 | AR5: 167509.54 | AS5: 167509.54 | AT5: 180878.22 | AU5: 167509.54 | AV5: =SUM(AG5:AU5) -> 3793629.8
B6: Load and haul 800 t fleet, flat, 2-5km | AA6: =SUM(X6:Z6) -> 0 | AF6: Load and haul 800 t fleet, flat, 2-5km | AV6: =SUM(AS6:AU6) -> 0
B7: Load and haul 800 t fleet, flat, >5km | AA7: =SUM(X7:Z7) -> 0 | AF7: Load and haul 800 t fleet, flat, >5km | AV7: =SUM(AS7:AU7) -> 0
B8: 600t fleet - Flat | AF8: 600t fleet - Flat
B9: Load and haul 600 t fleet, flat, <1km | AA9: =SUM(X9:Z9) -> 0 | AF9: Load and haul 600 t fleet, flat, <1km | AV9: =SUM(AS9:AU9) -> 0
B10: Load and haul 600 t fleet, flat, 1-2km | AA10: =SUM(X10:Z10) -> 0 | AF10: Load and haul 600 t fleet, flat, 1-2km | AV10: =SUM(AS10:AU10) -> 0
B11: Load and haul 600 t fleet, flat, 2-5km | AA11: =SUM(X11:Z11) -> 0 | AF11: Load and haul 600 t fleet, flat, 2-5km | AV11: =SUM(AS11:AU11) -> 0
B12: Load and haul 600 t fleet, flat, >5km | AA12: =SUM(X12:Z12) -> 0 | AF12: Load and haul 600 t fleet, flat, >5km | AV12: =SUM(AS12:AU12) -> 0
B13: 400t fleet - Flat | AF13: 400t fleet - Flat
B14: Load and haul 400 t fleet, flat, <1km | C14: 517079.75 | I14: 487189.06 | K14: 542263.77 | N14: 366634.47 | P14: 1539595.5 | AA14: =SUM(C14:Z14) -> 3452762.5 | AB14: Assumed the smaller Truck and Excavator Fleet will be applied. | AF14: Load and haul 400 t fleet, flat, <1km | AV14: =SUM(AG14:AU14) -> 0
B15: Load and haul 400 t fleet, flat, 1-2km | AA15: =SUM(X15:Z15) -> 0 | AF15: Load and haul 400 t fleet, flat, 1-2km | AV15: =SUM(AS15:AU15) -> 0
B16: Load and haul 400 t fleet, flat, 2-5km | AA16: =SUM(X16:Z16) -> 0 | AF16: Load and haul 400 t fleet, flat, 2-5km | AV16: =SUM(AS16:AU16) -> 0
B17: Load and haul 400 t fleet, flat, >5km | AA17: =SUM(X17:Z17) -> 0 | AF17: Load and haul 400 t fleet, flat, >5km | AV17: =SUM(AS17:AU17) -> 0
B18: 800 t fleet - 50m Elevation | AF18: 800 t fleet - 50m Elevation
B19: Load and haul 800 t fleet, 50m Elevation, <1km | AA19: =SUM(X19:Z19) -> 0 | AF19: Load and haul 800 t fleet, 50m Elevation, <1km | AV19: =SUM(AS19:AU19) -> 0
B20: Load and haul 800 t fleet, 50m Elevation, <1-2km | AA20: =SUM(X20:Z20) -> 0 | AF20: Load and haul 800 t fleet, 50m Elevation, <1-2km | AV20: =SUM(AS20:AU20) -> 0
B21: Load and haul 800 t fleet, 50m Elevation, 2-5km | AA21: =SUM(X21:Z21) -> 0 | AF21: Load and haul 800 t fleet, 50m Elevation, 2-5km | AV21: =SUM(AS21:AU21) -> 0
B22: Load and haul 800 t fleet, 50m Elevation, >5km | AA22: =SUM(X22:Z22) -> 0 | AF22: Load and haul 800 t fleet, 50m Elevation, >5km | AV22: =SUM(AS22:AU22) -> 0
B23: 600 t fleet - 50m Elevation | AF23: 600 t fleet - 50m Elevation
B24: Load and haul 600 t fleet, 50m Elevation, <1km | AA24: =SUM(X24:Z24) -> 0 | AF24: Load and haul 600 t fleet, 50m Elevation, <1km | AV24: =SUM(AS24:AU24) -> 0
B25: Load and haul 600 t fleet, 50m Elevation, <1-2km | AA25: =SUM(X25:Z25) -> 0 | AF25: Load and haul 600 t fleet, 50m Elevation, <1-2km | AV25: =SUM(AS25:AU25) -> 0
B26: Load and haul 600 t fleet, 50m Elevation, 2-5km | AA26: =SUM(X26:Z26) -> 0 | AF26: Load and haul 600 t fleet, 50m Elevation, 2-5km | AV26: =SUM(AS26:AU26) -> 0
B27: Load and haul 600 t fleet, 50m Elevation, >5km | AA27: =SUM(X27:Z27) -> 0 | AF27: Load and haul 600 t fleet, 50m Elevation, >5km | AV27: =SUM(AS27:AU27) -> 0
B28: 400 t fleet - 50m Elevation | AF28: 400 t fleet - 50m Elevation
B29: Load and haul 400 t fleet, 50m Elevation, <1km | AA29: =SUM(X29:Z29) -> 0 | AF29: Load and haul 400 t fleet, 50m Elevation, <1km | AV29: =SUM(AS29:AU29) -> 0
B30: Load and haul 400 t fleet, 50m Elevation, <1-2km | AA30: =SUM(X30:Z30) -> 0 | AF30: Load and haul 400 t fleet, 50m Elevation, <1-2km | AV30: =SUM(AS30:AU30) -> 0
B31: Load and haul 400 t fleet, 50m Elevation, 2-5km | AA31: =SUM(X31:Z31) -> 0 | AF31: Load and haul 400 t fleet, 50m Elevation, 2-5km | AV31: =SUM(AS31:AU31) -> 0
B32: Load and haul 400 t fleet, 50m Elevation, >5km | AA32: =SUM(X32:Z32) -> 0 | AF32: Load and haul 400 t fleet, 50m Elevation, >5km | AV32: =SUM(AS32:AU32) -> 0
B33: 800 t fleet - 100m Elevation | AF33: 800 t fleet - 100m Elevation
B34: Load and haul 800 t fleet, 100m Elevation, <1km | AA34: =SUM(X34:Z34) -> 0 | AF34: Load and haul 800 t fleet, 100m Elevation, <1km | AV34: =SUM(AS34:AU34) -> 0
B35: Load and haul 800 t fleet, 100m Elevation, <1-2km | AA35: =SUM(X35:Z35) -> 0 | AF35: Load and haul 800 t fleet, 100m Elevation, <1-2km | AV35: =SUM(AS35:AU35) -> 0
B36: Load and haul 800 t fleet, 100m Elevation, 2-5km | AA36: =SUM(X36:Z36) -> 0 | AF36: Load and haul 800 t fleet, 100m Elevation, 2-5km | AV36: =SUM(AS36:AU36) -> 0
B37: Load and haul 800 t fleet, 100m Elevation, >5km | AA37: =SUM(X37:Z37) -> 0 | AF37: Load and haul 800 t fleet, 100m Elevation, >5km | AV37: =SUM(AS37:AU37) -> 0
B38: 600 t fleet - 100m Elevation | AF38: 600 t fleet - 100m Elevation
B39: Load and haul 600 t fleet, 100m Elevation, <1km | AA39: =SUM(X39:Z39) -> 0 | AF39: Load and haul 600 t fleet, 100m Elevation, <1km | AV39: =SUM(AS39:AU39) -> 0
B40: Load and haul 600 t fleet, 100m Elevation, <1-2km | AA40: =SUM(X40:Z40) -> 0 | AF40: Load and haul 600 t fleet, 100m Elevation, <1-2km | AV40: =SUM(AS40:AU40) -> 0
...

Sheet Holding Costs
C2: Springbok Creek
B3: Holding Costs | C3: 2023 | D3: 2024 YTD | E3: 2024 Fcst | F3: Holding | G3: Execution 5 yr | H3: Post execution (15 yr) | I3: Total holding | J3: yr 1 | K3: yr 2 | L3: yr 3 | M3: yr 4 | N3: yr 5 | O3: yr 6 | P3: yr 7 | Q3: yr 8 | R3: yr 9 | S3: yr 10 | T3: yr 11 | U3: yr 12 | V3: yr 13 | W3: yr 14 | X3: yr 15
B4: 520110 | Technical Consulting Recharge | C4: 5487150.4 | D4: 3513622.3 | E4: 6023352.5 | F4: 1600000 | G4: =F4*5 -> 8000000 | H4: =SUM(J4:X4) -> 6352870.9 | I4: =SUM(G4:H4) -> 14352871 | J4: 800000 | K4: =J4*0.9 -> 720000 | L4: =K4*0.9 -> 648000 | M4: =L4*0.9 -> 583200 | N4: =M4*0.9 -> 524880 | O4: =N4*0.9 -> 472392 | P4: =O4*0.9 -> 425152.8 | Q4: =P4*0.9 -> 382637.52 | R4: =Q4*0.9 -> 344373.77 | ... X4: =W4*0.9 -> 183014.34
B5: 540320 | Bank Charges | C5: 157654.42 | D5: 363442.16 | E5: 623043.7 | F5: 623043.7 | G5: =F5*5 -> 3115218.5 | H5: =SUM(J5:X5) -> 4452880.8 | I5: =SUM(G5:H5) -> 7568099.3 | J5: =F5*0.9 -> 560739.33 | K5: =J5*0.9 -> 504665.4 | L5: =K5*0.9 -> 454198.86 | M5: =L5*0.9 -> 408778.97 | N5: =M5*0.9 -> 367901.08 | O5: =N5*0.9 -> 331110.97 | P5: =O5*0.9 -> 297999.87 | Q5: =P5*0.9 -> 268199.88 | R5: =Q5*0.9 -> 241379.9 | ... X5: =W5*0.9 -> 128279.17
B6: 540410 | Council Rates | C6: 8224499.1 | D6: 5397383.6 | E6: 9252657.5 | F6: 9252657.5 | G6: =F6*5 -> 46263288 | H6: =SUM(J6:X6) -> 66128557 | I6: =SUM(G6:H6) -> 1.1239184e+08 | J6: =F6*0.9 -> 8327391.8 | K6: =J6*0.9 -> 7494652.6 | L6: =K6*0.9 -> 6745187.3 | M6: =L6*0.9 -> 6070668.6 | N6: =M6*0.9 -> 5463601.7 | O6: =N6*0.9 -> 4917241.6 | P6: =O6*0.9 -> 4425517.4 | Q6: =P6*0.9 -> 3982965.7 | R6: =Q6*0.9 -> 3584669.1 | ... X6: =W6*0.9 -> 1905040.1
B7: 540450 | Land Tax | C7: 1857162.6 | D7: 1062435 | E7: 1821317.2 | F7: 1821317.2 | G7: =F7*5 -> 9106586.1 | H7: =SUM(J7:X7) -> 13016917 | I7: =SUM(G7:H7) -> 22123503 | J7: =F7*0.9 -> 1639185.5 | K7: =J7*0.9 -> 1475266.9 | L7: =K7*0.9 -> 1327740.2 | M7: =L7*0.9 -> 1194966.2 | N7: =M7*0.9 -> 1075469.6 | O7: =N7*0.9 -> 967922.64 | P7: =O7*0.9 -> 871130.38 | Q7: =P7*0.9 -> 784017.34 | R7: =Q7*0.9 -> 705615.6 | ... X7: =W7*0.9 -> 374993.06
B8: Town maintenance | C8: 0 | D8: 0 | E8: 0 | F8: 2000000 | G8: =F8*5 -> 10000000 | H8: =SUM(J8:X8) -> 14293960 | I8: =SUM(G8:H8) -> 24293960 | J8: =F8*0.9 -> 1800000 | K8: =J8*0.9 -> 1620000 | L8: =K8*0.9 -> 1458000 | M8: =L8*0.9 -> 1312200 | N8: =M8*0.9 -> 1180980 | O8: =N8*0.9 -> 1062882 | P8: =O8*0.9 -> 956593.8 | Q8: =P8*0.9 -> 860934.42 | R8: =Q8*0.9 -> 774840.98 | ... X8: =W8*0.9 -> 411782.26
B9: 540460 | Licences / Permits / Registrations | C9: 2574614.2 | D9: 1340811.7 | E9: 2298534.3 | F9: 2298534.3 | G9: =F9*5 -> 11492671 | H9: =SUM(J9:X9) -> 16427578 | I9: =SUM(G9:H9) -> 27920250 | J9: =F9*0.9 -> 2068680.9 | K9: =J9*0.9 -> 1861812.8 | L9: =K9*0.9 -> 1675631.5 | M9: =L9*0.9 -> 1508068.3 | N9: =M9*0.9 -> 1357261.5 | O9: =N9*0.9 -> 1221535.4 | P9: =O9*0.9 -> 1099381.8 | Q9: =P9*0.9 -> 989443.64 | R9: =Q9*0.9 -> 890499.28 | ... X9: =W9*0.9 -> 473247.83
B10: 540470 | Mine Subsidence Levy | C10: 0 | D10: 0 | E10: 0 | F10: 0 | G10: =F10*5 -> 0 | H10: =SUM(J10:X10) -> 0 | I10: =SUM(G10:H10) -> 0 | J10: =F10*0.9 -> 0 | K10: =J10*0.9 -> 0 | L10: =K10*0.9 -> 0 | M10: =L10*0.9 -> 0 | N10: =M10*0.9 -> 0 | O10: =N10*0.9 -> 0 | P10: =O10*0.9 -> 0 | Q10: =P10*0.9 -> 0 | R10: =Q10*0.9 -> 0 | ... X10: =W10*0.9 -> 0
B11: 540480 | Mines Rescue Levy | C11: 0 | D11: 0 | E11: 0 | F11: 0 | G11: =F11*5 -> 0 | H11: =SUM(J11:X11) -> 0 | I11: =SUM(G11:H11) -> 0 | J11: =F11*0.9 -> 0 | K11: =J11*0.9 -> 0 | L11: =K11*0.9 -> 0 | M11: =L11*0.9 -> 0 | N11: =M11*0.9 -> 0 | O11: =N11*0.9 -> 0 | P11: =O11*0.9 -> 0 | Q11: =P11*0.9 -> 0 | R11: =Q11*0.9 -> 0 | ... X11: =W11*0.9 -> 0
B12: 540510 | Insurance | C12: 16616587 | D12: 8873879.9 | E12: 15212365 | F12: 1500000 | G12: =F12*5 -> 7500000 | H12: =SUM(J12:X12) -> 10720470 | I12: =SUM(G12:H12) -> 18220470 | J12: =F12*0.9 -> 1350000 | K12: =J12*0.9 -> 1215000 | L12: =K12*0.9 -> 1093500 | M12: =L12*0.9 -> 984150 | N12: =M12*0.9 -> 885735 | O12: =N12*0.9 -> 797161.5 | P12: =O12*0.9 -> 717445.35 | Q12: =P12*0.9 -> 645700.81 | R12: =Q12*0.9 -> 581130.73 | ... X12: =W12*0.9 -> 308836.7
B13: 540620 | Legal Expenses - Tax Deductible | C13: 213924.91 | D13: 141153.75 | E13: 241977.86 | F13: 500000 | G13: =F13*5 -> 2500000 | H13: =SUM(J13:X13) -> 3573489.9 | I13: =SUM(G13:H13) -> 6073489.9 | J13: =F13*0.9 -> 450000 | K13: =J13*0.9 -> 405000 | L13: =K13*0.9 -> 364500 | M13: =L13*0.9 -> 328050 | N13: =M13*0.9 -> 295245 | O13: =N13*0.9 -> 265720.5 | P13: =O13*0.9 -> 239148.45 | Q13: =P13*0.9 -> 215233.61 | R13: =Q13*0.9 -> 193710.24 | ... X13: =W13*0.9 -> 102945.57
B14: 540760 | Shared Services Fee | C14: 270000.13 | D14: 174953.09 | E14: 299919.58 | F14: 0 | G14: =F14*5 -> 0 | H14: =SUM(J14:X14) -> 0 | I14: =SUM(G14:H14) -> 0 | J14: =F14*0.9 -> 0 | K14: =J14*0.9 -> 0 | L14: =K14*0.9 -> 0 | M14: =L14*0.9 -> 0 | N14: =M14*0.9 -> 0 | O14: =N14*0.9 -> 0 | P14: =O14*0.9 -> 0 | Q14: =P14*0.9 -> 0 | R14: =Q14*0.9 -> 0 | ... X14: =W14*0.9 -> 0
C16: =SUM(C4:C14) -> 35401593 | D16: =SUM(D4:D14) -> 20867681 | E16: =SUM(E4:E14) -> 35773168 | F16: =SUM(F4:F14) -> 19595553 | G16: =SUM(G4:G14) -> 97977764 | H16: =SUM(H4:H14) -> 1.3496672e+08 | I16: =SUM(I4:I14) -> 2.3294449e+08

Sheet 2024 Cost Schedule for Tool
C1: 1 | D1: 2 | E1: 3 | F1: 5
C3: WM Mine Closure Rates
C7: # | D7: Activity / Description | E7: Unit | F7: WM 2024 Rate
B9: Activity | C9: 1 | D9: Termination of Services and Demolition Works
B10: Demo | C10: 1.01 | D10: Disconnect and terminate all services (Water, electricity, gas etc. at point of attachment to site) | E10: @ | F10: 47518.457
B11: Demo | C11: 1.02 | D11: Disconnect and terminate services at remote areas (admin buildings, workshops) | E11: @ | F11: 9490.4819
B12: Demo | C12: 1.03 | D12: Removal of power lines (this includes disconnection, rolling up the wires and removing the poles). It does not include the removal of substations. | E12: km | F12: 17002.238
B13: Demo | C13: 1.04 | D13: Removal of >66kV power lines (this includes disconnection, rolling up the wires and removing the poles). It does not include the removal of substations. | E13: km | F13: 112646.67
B14: Demo | C14: 1.05a | D14: Remove small rail, road, water course overpass - smaller structure with minimal civil works | E14: Item | F14: 394263.34
B15: Demo | C15: 1.05b | D15: Remove medium rail, road, water course overpass - medium structure with minimal civil works | E15: Item | F15: 563233.34
B16: Demo | C16: 1.05c | D16: Remove large/significant rail, road, water course overpass - large structure with significant water management and civil works | E16: Item | F16: 2186002.1
B17: Demo | C17: 1.06 | D17: Demolish and/or remove substations (Assumes they are in a closed building) | E17: m2 | F17: 701.8524
B18: Demo | C18: 1.07 | D18: Demolish and remove switchyard/gas flare plant | E18: m2 | F18: 73.548396
B19: Demo | C19: 1.08 | D19: Demolish and remove demountable structures on concrete stumps - assumes not being re-used | E19: m2 | F19: 45.058668
B20: Demo | C20: 1.08a | D20: Demolish and remove demountable structures on concrete stumps - assumes not being re-used - each | E20: Unit | F20: 2467.2437
B21: Demo | C21: 1.09 | D21: Demolish and remove small buildings/tanks (admin buildings, single story accommodation etc.) | E21: m2 | F21: 91.359913
B22: Demo | C22: 1.1 | D22: Demolish and remove light industrial buildings | E22: m2/floor | F22: 92.297865
B23: Demo | C23: 1.11 | D23: Demolish and remove industrial buildings (workshops tyre change and servicing area etc. - not CHPP) | E23: m2/floor | F23: 175.7288
B24: Demo | C24: 1.12 | D24: Demolish and remove CHPP (include the area of each floor of the structure) | E24: m2/floor | F24: 247.82643
B25: Demo | C25: 1.13 | D25: Demolish and remove crushers, hoppers, sizing stations, rotary breakers, etc. (include the area of each floor of the structure). | E25: m2/floor | F25: 253.455
B26: Demo | C26: 1.14 | D26: Demolish and remove stacker or reclaimer (radial or luffing etc.) | E26: @ | F26: 1099045.8
B27: Demo | C27: 1.15 | D27: Demolish and remove bucket wheel stacker/reclaimer | E27: @ | F27: 2252933.4
B28: Demo | C28: 1.16 | D28: Remove stacker/reclaimer rails and ballast etc. | E28: m | F28: 84.485002
B29: Demo | C29: 1.17 | D29: Collapse, Cut and Remove 5000T coal silo | E29: @ | F29: 123726.65
B30: Demo | C30: 1.18 | D30: Collapse, Cut and Remove 2000/3000 T coal silo | E30: @ | F30: 104120.73
B31: Demo | C31: 1.19 | D31: Collapse, Cut and Remove 1250 T coal silo | E31: @ | F31: 77940.938
B32: Demo | C32: 1.2 | D32: Collapse, Cut and Remove rail loading bins | E32: @ | F32: 76881.352
B33: Demo | C33: 1.20a | D33: Demolish and Remove large concrete rail loading bin - and disposal on-site/locally | E33: allow | F33: 518174.68
B34: Demo | C34: 1.21 | D34: Demolish and remove on-ground conveyors, transfer stations & gantries (scrap only – does not include dismantling for reuse at another site) | E34: m | F34: 225.64273
B35: Demo | C35: 1.22 | D35: Demolish and remove elevated conveyors, transfer stations & gantries (scrap only – does not include dismantling for reuse at another site) | E35: m | F35: 463.05751
B36: Demo | C36: 1.23 | D36: Demolish and remove overhead conveyors, transfer stations & gantries (scrap only – does not include dismantling for reuse at another site) | E36: m | F36: 957.49669
B37: Demo | C37: 1.24 | D37: Demolish reclaim tunnel, cut reo and expose reclaim conveyor, then collapse into the reclaim tunnel void (Does not include excavation to expose reclaim tunnel, removal of conveyor or backfilling void) | E37: m2 | F37: 107.01434
B38: Demo | C38: 1.25 | D38: Remove and demolish conveyor from reclaim tunnel (Does not include excavation and demolition of reclaim tunnel roof) | E38: m | F38: 168.97
B39: Demo | C39: 1.26 | D39: Demolition of reclaim tunnel concrete (Assumes complete removal and dumping in mine pit void) | E39: m | F39: 1070.1434
B40: Demo | C40: 1.27 | D40: Demolition and removal of vent raise fans, electrical substation and winch | E40: @ | F40: 50127.768
B41: Demo | C41: 1.28 | D41: Demolish and remove small tank clean (Thickener etc. 3 - 9 m diameter) | E41: @ | F41: 11264.667
B42: Demo | C42: 1.29 | D42: Demolish and remove medium tank clean (Thickener etc. 10 - 15 m diameter) | E42: @ | F42: 33794.001
B43: Demo | C43: 1.3 | D43: Demolish and remove large tank clean (Thickener etc. 15 - 30 m diameter) | E43: @ | F43: 72094.244
B44: Demo | C44: 1.31 | D44: Demolish and remove extra large tank clean (Thickener etc. >30 m diameter) | E44: @ | F44: 104198.17
B45: Demo | C45: 1.32 | D45: Demolish and remove tank clean (Thickener etc.) >50 m diameter | E45: @ | F45: 197131.67
...
