Workbook
Name A: #REF!
Name a: Springbok!$D$69:$W$69
Name Ac: #REF!
Name Ac: #REF!
Name afhKJADF: #REF!
Name afhKJADF: #REF!
Name C_C_Balance: #REF!
Name C_C_Balance: #REF!
Name coalfield: #REF!
Name CoalPP: #REF!
Name CPP: #REF!
Name CPP: #REF!
Name CPPe: #REF!
Name CPPe: #REF!
Name CPPout: #REF!
Name CPPout: #REF!
Name Critical_Component: #REF!
Name Critical_Component: #REF!
Name d: #REF!
Name d: #REF!
Name Db: #REF!
Name Db: #REF!
Name Dc: #REF!
Name Dc: #REF!
Name Deisel: #REF!
Name Deisel: #REF!
Name diesel: #REF!
Name diesel: #REF!
Name Effective_Tax_Rate: #REF!
Name Effective_Tax_Rate: #REF!
Name Elunits: #REF!
Name Em: #REF!
Name Em: #REF!
Name equiptype: #REF!
Name Es: #REF!
Name Es: #REF!
Name f: #REF!
Name f: #REF!
Name Factor: #REF!
Name Factor: #REF!
Name Fuel: #REF!
Name FuelList: #REF!
Name FuelTypes: #REF!
Name FuelTypes: #REF!
Name Fueluse: #REF!
Name Fueluse: #REF!
Name gs: #REF!
Name gs: #REF!
Name H: #REF!
Name H: #REF!
Name HFC: #REF!
Name HFCunit: #REF!
Name howoften: #REF!
Name km: #REF!
Name L: #REF!
Name L: #REF!
Name Liquidunits: #REF!
Name LPG: #REF!
Name LPG: #REF!
Name LVkm: #REF!

Sheet Assumptions
A1: Corporate Assumptions | D1: =E1-1 -> 2021 | E1: =F1-1 -> 2022 | F1: =G1-1 -> 2023 | G1: =H1-1 -> 2024 | H1: =I1-1 -> 2025 | I1: 2026 | J1: =I1+1 -> 2027 | K1: =J1+1 -> 2028 | L1: =K1+1 -> 2029 | M1: =L1+1 -> 2030 | N1: =M1+1 -> 2031 | O1: =N1+1 -> 2032 | P1: =O1+1 -> 2033 | Q1: =P1+1 -> 2034 | ... BV1: =BU1+1 -> 2091
A2: Discount Rate | B2: 0.08 | D2: 1 | E2: 1 | F2: 1 | G2: 1 | H2: 1 | I2: =(1+$B2)^-(I$1-$I$1+0.5) -> 0.96225045 | J2: =(1+$B2)^-(J$1-$I$1+0.5) -> 0.89097264 | K2: =(1+$B2)^-(K$1-$I$1+0.5) -> 0.82497466 | L2: =(1+$B2)^-(L$1-$I$1+0.5) -> 0.76386543 | M2: =(1+$B2)^-(M$1-$I$1+0.5) -> 0.70728281 | N2: =(1+$B2)^-(N$1-$I$1+0.5) -> 0.65489149 | O2: =(1+$B2)^-(O$1-$I$1+0.5) -> 0.60638101 | P2: =(1+$B2)^-(P$1-$I$1+0.5) -> 0.56146389 | ... BV2: =(1+$B2)^-(BV$1-$I$1+0.5) -> 0.0064676129
A3: Foreign Exchange Forecast
A4: Foreign Exchange Rate | B4: USD:AUD | D4: 0.743 | E4: 0.694 | F4: 0.6646 | G4: 0.6629 | H4: 0.6306 | I4: 0.69 | J4: 0.69 | K4: 0.69 | L4: 0.69 | M4: 0.69 | N4: =M4 -> 0.69 | O4: =N4 -> 0.69 | P4: =O4 -> 0.69 | Q4: =P4 -> 0.69 | R4: =Q4 -> 0.69 | S4: =R4 -> 0.69 | T4: =S4 -> 0.69 | U4: =T4 -> 0.69 | ... BV4: =BU4 -> 0.69
A5: Pricing Forecasts (real terms 2023)
A6: Premium Hard Coking Coal | B6: USD/t | C6: PLV | D6: ='Historical Performance'!D23 -> 295 | E6: ='Historical Performance'!E23 -> 360 | F6: ='Historical Performance'!F23 -> 345 | G6: ='Historical Performance'!G23 -> 310 | H6: ='Historical Performance'!H23 -> 300 | I6: ='Historical Performance'!I23 -> 315 | J6: 240 | K6: 240 | L6: 240 | M6: 240 | N6: =M6 -> 240 | O6: =N6 -> 240 | P6: =O6 -> 240 | Q6: =P6 -> 240 | R6: =Q6 -> 240 | S6: =R6 -> 240 | T6: =S6 -> 240 | U6: =T6 -> 240 | ... BV6: =BU6 -> 240
A7: 88% PHCC | B7: USD/t | C7: Benchmark | J7: =J6*0.88 -> 211.2 | K7: =K6*0.88 -> 211.2 | L7: =L6*0.88 -> 211.2 | M7: =M6*0.88 -> 211.2 | N7: =M7 -> 211.2 | O7: =N7 -> 211.2 | P7: =O7 -> 211.2 | Q7: =P7 -> 211.2 | R7: =Q7 -> 211.2 | S7: =R7 -> 211.2 | T7: =S7 -> 211.2 | U7: =T7 -> 211.2 | ... BV7: =BU7 -> 211.2
A8: 6000NAR (GCN) | B8: USD/t | C8: Thermal Product A | J8: 118 | K8: 118 | L8: 118 | M8: 118 | N8: 118 | O8: 118 | P8: 118 | Q8: 118 | R8: 118 | S8: 118 | T8: 118 | U8: 118 | V8: 118 | W8: 118 | X8: 118 | Y8: 118 | Z8: 118 | AA8: 118 | AB8: 118 | AC8: 118 | AD8: 118 | AE8: 118 | AF8: 118 | AG8: 118 | AH8: 118 | AI8: 118 | AJ8: 118 | AK8: 118 | AL8: 118 | AM8: 118 | AN8: 118 | AO8: 118 | AP8: 118 | AQ8: 118 | AR8: 118 | AS8: 118 | AT8: 118 | AU8: 118 | AV8: 118 | AW8: 118 | AX8: 118 | AY8: 118 | AZ8: 118 | BA8: 118 | BB8: 118 | BC8: 118 | BD8: 118 | BE8: 118 | BF8: 118 | BG8: 118 | BH8: 118 | BI8: 118 | BJ8: 118 | BK8: 118 | BL8: 118 | BM8: 118 | BN8: 118 | BO8: 118 | BP8: 118 | BQ8: 118 | BR8: 118 | BS8: 118 | BT8: 118 | BU8: 118 | BV8: 118
A9: 5500NAR | B9: USD/t | C9: Thermal Product B | J9: 105 | K9: 105 | L9: 105 | M9: 105 | N9: 105 | O9: 105 | P9: 105 | Q9: 105 | R9: 105 | S9: 105 | T9: 105 | U9: 105 | V9: 105 | W9: 105 | X9: 105 | Y9: 105 | Z9: 105 | AA9: 105 | AB9: 105 | AC9: 105 | AD9: 105 | AE9: 105 | AF9: 105 | AG9: 105 | AH9: 105 | AI9: 105 | AJ9: 105 | AK9: 105 | AL9: 105 | AM9: 105 | AN9: 105 | AO9: 105 | AP9: 105 | AQ9: 105 | AR9: 105 | AS9: 105 | AT9: 105 | AU9: 105 | AV9: 105 | AW9: 105 | AX9: 105 | AY9: 105 | AZ9: 105 | BA9: 105 | BB9: 105 | BC9: 105 | BD9: 105 | BE9: 105 | BF9: 105 | BG9: 105 | BH9: 105 | BI9: 105 | BJ9: 105 | BK9: 105 | BL9: 105 | BM9: 105 | BN9: 105 | BO9: 105 | BP9: 105 | BQ9: 105 | BR9: 105 | BS9: 105 | BT9: 105 | BU9: 105 | BV9: 105
A11: Thermal Categories | I11: Thermal category minimum spec
A12: Benchmark Thermal | B12: kcal/kg(nar) | I12: 5950 | J12: 5950 | K12: 5950 | L12: 5950 | M12: 5950 | N12: 5950 | O12: 5950 | P12: 5950 | Q12: 5950 | R12: 5950 | S12: 5950 | T12: 5950 | U12: 5950 | V12: 5950 | W12: 5950 | X12: 5950 | Y12: 5950 | Z12: 5950 | AA12: 5950 | AB12: 5950 | AC12: 5950 | AD12: 5950 | AE12: 5950 | AF12: 5950 | AG12: 5950 | AH12: 5950 | AI12: 5950 | AJ12: 5950 | AK12: 5950 | AL12: 5950 | AM12: 5950 | AN12: 5950 | AO12: 5950 | AP12: 5950 | AQ12: 5950 | AR12: 5950 | AS12: 5950 | AT12: 5950 | AU12: 5950 | AV12: 5950 | AW12: 5950 | AX12: 5950 | AY12: 5950 | AZ12: 5950 | BA12: 5950 | BB12: 5950 | BC12: 5950 | BD12: 5950 | BE12: 5950 | BF12: 5950 | BG12: 5950 | BH12: 5950 | BI12: 5950 | BJ12: 5950 | BK12: 5950 | BL12: 5950 | BM12: 5950 | BN12: 5950 | BO12: 5950 | BP12: 5950 | BQ12: 5950 | BR12: 5950 | BS12: 5950 | BT12: 5950 | BU12: 5950 | BV12: 5950
A13: 5500NAR | B13: kcal/kg(nar) | I13: 5300 | J13: 5300 | K13: 5300 | L13: 5300 | M13: 5300 | N13: 5300 | O13: 5300 | P13: 5300 | Q13: 5300 | R13: 5300 | S13: 5300 | T13: 5300 | U13: 5300 | V13: 5300 | W13: 5300 | X13: 5300 | Y13: 5300 | Z13: 5300 | AA13: 5300 | AB13: 5300 | AC13: 5300 | AD13: 5300 | AE13: 5300 | AF13: 5300 | AG13: 5300 | AH13: 5300 | AI13: 5300 | AJ13: 5300 | AK13: 5300 | AL13: 5300 | AM13: 5300 | AN13: 5300 | AO13: 5300 | AP13: 5300 | AQ13: 5300 | AR13: 5300 | AS13: 5300 | AT13: 5300 | AU13: 5300 | AV13: 5300 | AW13: 5300 | AX13: 5300 | AY13: 5300 | AZ13: 5300 | BA13: 5300 | BB13: 5300 | BC13: 5300 | BD13: 5300 | BE13: 5300 | BF13: 5300 | BG13: 5300 | BH13: 5300 | BI13: 5300 | BJ13: 5300 | BK13: 5300 | BL13: 5300 | BM13: 5300 | BN13: 5300 | BO13: 5300 | BP13: 5300 | BQ13: 5300 | BR13: 5300 | BS13: 5300 | BT13: 5300 | BU13: 5300 | BV13: 5300
A14: 5100NAR | B14: kcal/kg(nar) | I14: 0 | J14: 0 | K14: 0 | L14: 0 | M14: 0 | N14: 0 | O14: 0 | P14: 0 | Q14: 0 | R14: 0 | S14: 0 | T14: 0 | U14: 0 | V14: 0 | W14: 0 | X14: 0 | Y14: 0 | Z14: 0 | AA14: 0 | AB14: 0 | AC14: 0 | AD14: 0 | AE14: 0 | AF14: 0 | AG14: 0 | AH14: 0 | AI14: 0 | AJ14: 0 | AK14: 0 | AL14: 0 | AM14: 0 | AN14: 0 | AO14: 0 | AP14: 0 | AQ14: 0 | AR14: 0 | AS14: 0 | AT14: 0 | AU14: 0 | AV14: 0 | AW14: 0 | AX14: 0 | AY14: 0 | AZ14: 0 | BA14: 0 | BB14: 0 | BC14: 0 | BD14: 0 | BE14: 0 | BF14: 0 | BG14: 0 | BH14: 0 | BI14: 0 | BJ14: 0 | BK14: 0 | BL14: 0 | BM14: 0 | BN14: 0 | BO14: 0 | BP14: 0 | BQ14: 0 | BR14: 0 | BS14: 0 | BT14: 0 | BU14: 0 | BV14: 0
A16: GAR-> NAR adjustment | B16: 260 | C16: kcal/kg
A17: Basis of coal prices | B17: 6000 | C17: kcal/kg(nar)
A20: Carbon Scenario | C20: Accelerated Transition
A23: Other Assumptions
A25: QLD royalty assumptions
A27: Threshold
A28: Tier 1 | B28: AUD/t | D28: 0 | E28: 0 | F28: 0 | G28: 0 | H28: 0 | I28: 0 | J28: 0 | K28: 0 | L28: 0 | M28: 0 | N28: 0 | O28: 0 | P28: 0 | Q28: 0 | R28: 0 | S28: 0 | T28: 0 | U28: 0 | V28: 0 | W28: 0 | X28: 0 | Y28: 0 | Z28: 0 | AA28: 0 | AB28: 0 | AC28: 0 | AD28: 0 | AE28: 0 | AF28: 0 | AG28: 0 | AH28: 0 | AI28: 0 | AJ28: 0 | AK28: 0 | AL28: 0 | AM28: 0 | AN28: 0 | AO28: 0 | AP28: 0 | AQ28: 0 | AR28: 0 | AS28: 0 | AT28: 0 | AU28: 0 | AV28: 0 | AW28: 0 | AX28: 0 | AY28: 0 | AZ28: 0 | BA28: 0 | BB28: 0 | BC28: 0 | BD28: 0 | BE28: 0 | BF28: 0 | BG28: 0 | BH28: 0 | BI28: 0 | BJ28: 0 | BK28: 0 | BL28: 0 | BM28: 0 | BN28: 0 | BO28: 0 | BP28: 0 | BQ28: 0 | BR28: 0 | BS28: 0 | BT28: 0 | BU28: 0 | BV28: 0
A29: Tier 2 | B29: AUD/t | D29: 100 | E29: 100 | F29: 100 | G29: 100 | H29: 100 | I29: 100 | J29: 100 | K29: 100 | L29: 100 | M29: 100 | N29: 100 | O29: 100 | P29: 100 | Q29: 100 | R29: 100 | S29: 100 | T29: 100 | U29: 100 | V29: 100 | W29: 100 | X29: 100 | Y29: 100 | Z29: 100 | AA29: 100 | AB29: 100 | AC29: 100 | AD29: 100 | AE29: 100 | AF29: 100 | AG29: 100 | AH29: 100 | AI29: 100 | AJ29: 100 | AK29: 100 | AL29: 100 | AM29: 100 | AN29: 100 | AO29: 100 | AP29: 100 | AQ29: 100 | AR29: 100 | AS29: 100 | AT29: 100 | AU29: 100 | AV29: 100 | AW29: 100 | AX29: 100 | AY29: 100 | AZ29: 100 | BA29: 100 | BB29: 100 | BC29: 100 | BD29: 100 | BE29: 100 | BF29: 100 | BG29: 100 | BH29: 100 | BI29: 100 | BJ29: 100 | BK29: 100 | BL29: 100 | BM29: 100 | BN29: 100 | BO29: 100 | BP29: 100 | BQ29: 100 | BR29: 100 | BS29: 100 | BT29: 100 | BU29: 100 | BV29: 100
A30: Tier 3 | B30: AUD/t | D30: 150 | E30: 150 | F30: 150 | G30: 150 | H30: 150 | I30: 150 | J30: 150 | K30: 150 | L30: 150 | M30: 150 | N30: 150 | O30: 150 | P30: 150 | Q30: 150 | R30: 150 | S30: 150 | T30: 150 | U30: 150 | V30: 150 | W30: 150 | X30: 150 | Y30: 150 | Z30: 150 | AA30: 150 | AB30: 150 | AC30: 150 | AD30: 150 | AE30: 150 | AF30: 150 | AG30: 150 | AH30: 150 | AI30: 150 | AJ30: 150 | AK30: 150 | AL30: 150 | AM30: 150 | AN30: 150 | AO30: 150 | AP30: 150 | AQ30: 150 | AR30: 150 | AS30: 150 | AT30: 150 | AU30: 150 | AV30: 150 | AW30: 150 | AX30: 150 | AY30: 150 | AZ30: 150 | BA30: 150 | BB30: 150 | BC30: 150 | BD30: 150 | BE30: 150 | BF30: 150 | BG30: 150 | BH30: 150 | BI30: 150 | BJ30: 150 | BK30: 150 | BL30: 150 | BM30: 150 | BN30: 150 | BO30: 150 | BP30: 150 | BQ30: 150 | BR30: 150 | BS30: 150 | BT30: 150 | BU30: 150 | BV30: 150
A31: Tier 4 | B31: AUD/t | F31: 175 | G31: 175 | H31: 175 | I31: 175 | J31: 175 | K31: 175 | L31: 175 | M31: 175 | N31: 175 | O31: 175 | P31: 175 | Q31: 175 | R31: 175 | S31: 175 | T31: 175 | U31: 175 | V31: 175 | W31: 175 | X31: 175 | Y31: 175 | Z31: 175 | AA31: 175 | AB31: 175 | AC31: 175 | AD31: 175 | AE31: 175 | AF31: 175 | AG31: 175 | AH31: 175 | AI31: 175 | AJ31: 175 | AK31: 175 | AL31: 175 | AM31: 175 | AN31: 175 | AO31: 175 | AP31: 175 | AQ31: 175 | AR31: 175 | AS31: 175 | AT31: 175 | AU31: 175 | AV31: 175 | AW31: 175 | AX31: 175 | AY31: 175 | AZ31: 175 | BA31: 175 | BB31: 175 | BC31: 175 | BD31: 175 | BE31: 175 | BF31: 175 | BG31: 175 | BH31: 175 | BI31: 175 | BJ31: 175 | BK31: 175 | BL31: 175 | BM31: 175 | BN31: 175 | BO31: 175 | BP31: 175 | BQ31: 175 | BR31: 175 | BS31: 175 | BT31: 175 | BU31: 175 | BV31: 175
A32: Tier 5 | B32: AUD/t | F32: 225 | G32: 225 | H32: 225 | I32: 225 | J32: 225 | K32: 225 | L32: 225 | M32: 225 | N32: 225 | O32: 225 | P32: 225 | Q32: 225 | R32: 225 | S32: 225 | T32: 225 | U32: 225 | V32: 225 | W32: 225 | X32: 225 | Y32: 225 | Z32: 225 | AA32: 225 | AB32: 225 | AC32: 225 | AD32: 225 | AE32: 225 | AF32: 225 | AG32: 225 | AH32: 225 | AI32: 225 | AJ32: 225 | AK32: 225 | AL32: 225 | AM32: 225 | AN32: 225 | AO32: 225 | AP32: 225 | AQ32: 225 | AR32: 225 | AS32: 225 | AT32: 225 | AU32: 225 | AV32: 225 | AW32: 225 | AX32: 225 | AY32: 225 | AZ32: 225 | BA32: 225 | BB32: 225 | BC32: 225 | BD32: 225 | BE32: 225 | BF32: 225 | BG32: 225 | BH32: 225 | BI32: 225 | BJ32: 225 | BK32: 225 | BL32: 225 | BM32: 225 | BN32: 225 | BO32: 225 | BP32: 225 | BQ32: 225 | BR32: 225 | BS32: 225 | BT32: 225 | BU32: 225 | BV32: 225
A33: Tier 6 | B33: AUD/t | F33: 300 | G33: 300 | H33: 300 | I33: 300 | J33: 300 | K33: 300 | L33: 300 | M33: 300 | N33: 300 | O33: 300 | P33: 300 | Q33: 300 | R33: 300 | S33: 300 | T33: 300 | U33: 300 | V33: 300 | W33: 300 | X33: 300 | Y33: 300 | Z33: 300 | AA33: 300 | AB33: 300 | AC33: 300 | AD33: 300 | AE33: 300 | AF33: 300 | AG33: 300 | AH33: 300 | AI33: 300 | AJ33: 300 | AK33: 300 | AL33: 300 | AM33: 300 | AN33: 300 | AO33: 300 | AP33: 300 | AQ33: 300 | AR33: 300 | AS33: 300 | AT33: 300 | AU33: 300 | AV33: 300 | AW33: 300 | AX33: 300 | AY33: 300 | AZ33: 300 | BA33: 300 | BB33: 300 | BC33: 300 | BD33: 300 | BE33: 300 | BF33: 300 | BG33: 300 | BH33: 300 | BI33: 300 | BJ33: 300 | BK33: 300 | BL33: 300 | BM33: 300 | BN33: 300 | BO33: 300 | BP33: 300 | BQ33: 300 | BR33: 300 | BS33: 300 | BT33: 300 | BU33: 300 | BV33: 300
A34: Rate
A35: Tier 1 | B35: % | D35: 0.07 | E35: 0.07 | F35: 0.07 | G35: 0.07 | H35: 0.07 | I35: 0.07 | J35: 0.07 | K35: 0.07 | L35: 0.07 | M35: 0.07 | N35: 0.07 | O35: 0.07 | P35: 0.07 | Q35: 0.07 | R35: 0.07 | S35: 0.07 | T35: 0.07 | U35: 0.07 | V35: 0.07 | W35: 0.07 | X35: 0.07 | Y35: 0.07 | Z35: 0.07 | AA35: 0.07 | AB35: 0.07 | AC35: 0.07 | AD35: 0.07 | AE35: 0.07 | AF35: 0.07 | AG35: 0.07 | AH35: 0.07 | AI35: 0.07 | AJ35: 0.07 | AK35: 0.07 | AL35: 0.07 | AM35: 0.07 | AN35: 0.07 | AO35: 0.07 | AP35: 0.07 | AQ35: 0.07 | AR35: 0.07 | AS35: 0.07 | AT35: 0.07 | AU35: 0.07 | AV35: 0.07 | AW35: 0.07 | AX35: 0.07 | AY35: 0.07 | AZ35: 0.07 | BA35: 0.07 | BB35: 0.07 | BC35: 0.07 | BD35: 0.07 | BE35: 0.07 | BF35: 0.07 | BG35: 0.07 | BH35: 0.07 | BI35: 0.07 | BJ35: 0.07 | BK35: 0.07 | BL35: 0.07 | BM35: 0.07 | BN35: 0.07 | BO35: 0.07 | BP35: 0.07 | BQ35: 0.07 | BR35: 0.07 | BS35: 0.07 | BT35: 0.07 | BU35: 0.07 | BV35: 0.07
A36: Tier 2 | B36: % | D36: 0.125 | E36: 0.125 | F36: 0.125 | G36: 0.125 | H36: 0.125 | I36: 0.125 | J36: 0.125 | K36: 0.125 | L36: 0.125 | M36: 0.125 | N36: 0.125 | O36: 0.125 | P36: 0.125 | Q36: 0.125 | R36: 0.125 | S36: 0.125 | T36: 0.125 | U36: 0.125 | V36: 0.125 | W36: 0.125 | X36: 0.125 | Y36: 0.125 | Z36: 0.125 | AA36: 0.125 | AB36: 0.125 | AC36: 0.125 | AD36: 0.125 | AE36: 0.125 | AF36: 0.125 | AG36: 0.125 | AH36: 0.125 | AI36: 0.125 | AJ36: 0.125 | AK36: 0.125 | AL36: 0.125 | AM36: 0.125 | AN36: 0.125 | AO36: 0.125 | AP36: 0.125 | AQ36: 0.125 | AR36: 0.125 | AS36: 0.125 | AT36: 0.125 | AU36: 0.125 | AV36: 0.125 | AW36: 0.125 | AX36: 0.125 | AY36: 0.125 | AZ36: 0.125 | BA36: 0.125 | BB36: 0.125 | BC36: 0.125 | BD36: 0.125 | BE36: 0.125 | BF36: 0.125 | BG36: 0.125 | BH36: 0.125 | BI36: 0.125 | BJ36: 0.125 | BK36: 0.125 | BL36: 0.125 | BM36: 0.125 | BN36: 0.125 | BO36: 0.125 | BP36: 0.125 | BQ36: 0.125 | BR36: 0.125 | BS36: 0.125 | BT36: 0.125 | BU36: 0.125 | BV36: 0.125
A37: Tier 3 | B37: % | D37: 0.15 | E37: 0.15 | F37: 0.15 | G37: 0.15 | H37: 0.15 | I37: 0.15 | J37: 0.15 | K37: 0.15 | L37: 0.15 | M37: 0.15 | N37: 0.15 | O37: 0.15 | P37: 0.15 | Q37: 0.15 | R37: 0.15 | S37: 0.15 | T37: 0.15 | U37: 0.15 | V37: 0.15 | W37: 0.15 | X37: 0.15 | Y37: 0.15 | Z37: 0.15 | AA37: 0.15 | AB37: 0.15 | AC37: 0.15 | AD37: 0.15 | AE37: 0.15 | AF37: 0.15 | AG37: 0.15 | AH37: 0.15 | AI37: 0.15 | AJ37: 0.15 | AK37: 0.15 | AL37: 0.15 | AM37: 0.15 | AN37: 0.15 | AO37: 0.15 | AP37: 0.15 | AQ37: 0.15 | AR37: 0.15 | AS37: 0.15 | AT37: 0.15 | AU37: 0.15 | AV37: 0.15 | AW37: 0.15 | AX37: 0.15 | AY37: 0.15 | AZ37: 0.15 | BA37: 0.15 | BB37: 0.15 | BC37: 0.15 | BD37: 0.15 | BE37: 0.15 | BF37: 0.15 | BG37: 0.15 | BH37: 0.15 | BI37: 0.15 | BJ37: 0.15 | BK37: 0.15 | BL37: 0.15 | BM37: 0.15 | BN37: 0.15 | BO37: 0.15 | BP37: 0.15 | BQ37: 0.15 | BR37: 0.15 | BS37: 0.15 | BT37: 0.15 | BU37: 0.15 | BV37: 0.15
A38: Tier 4 | B38: % | F38: 0.2 | G38: 0.2 | H38: 0.2 | I38: 0.2 | J38: 0.2 | K38: 0.2 | L38: 0.2 | M38: 0.2 | N38: 0.2 | O38: 0.2 | P38: 0.2 | Q38: 0.2 | R38: 0.2 | S38: 0.2 | T38: 0.2 | U38: 0.2 | V38: 0.2 | W38: 0.2 | X38: 0.2 | Y38: 0.2 | Z38: 0.2 | AA38: 0.2 | AB38: 0.2 | AC38: 0.2 | AD38: 0.2 | AE38: 0.2 | AF38: 0.2 | AG38: 0.2 | AH38: 0.2 | AI38: 0.2 | AJ38: 0.2 | AK38: 0.2 | AL38: 0.2 | AM38: 0.2 | AN38: 0.2 | AO38: 0.2 | AP38: 0.2 | AQ38: 0.2 | AR38: 0.2 | AS38: 0.2 | AT38: 0.2 | AU38: 0.2 | AV38: 0.2 | AW38: 0.2 | AX38: 0.2 | AY38: 0.2 | AZ38: 0.2 | BA38: 0.2 | BB38: 0.2 | BC38: 0.2 | BD38: 0.2 | BE38: 0.2 | BF38: 0.2 | BG38: 0.2 | BH38: 0.2 | BI38: 0.2 | BJ38: 0.2 | BK38: 0.2 | BL38: 0.2 | BM38: 0.2 | BN38: 0.2 | BO38: 0.2 | BP38: 0.2 | BQ38: 0.2 | BR38: 0.2 | BS38: 0.2 | BT38: 0.2 | BU38: 0.2 | BV38: 0.2
A39: Tier 5 | B39: % | F39: 0.3 | G39: 0.3 | H39: 0.3 | I39: 0.3 | J39: 0.3 | K39: 0.3 | L39: 0.3 | M39: 0.3 | N39: 0.3 | O39: 0.3 | P39: 0.3 | Q39: 0.3 | R39: 0.3 | S39: 0.3 | T39: 0.3 | U39: 0.3 | V39: 0.3 | W39: 0.3 | X39: 0.3 | Y39: 0.3 | Z39: 0.3 | AA39: 0.3 | AB39: 0.3 | AC39: 0.3 | AD39: 0.3 | AE39: 0.3 | AF39: 0.3 | AG39: 0.3 | AH39: 0.3 | AI39: 0.3 | AJ39: 0.3 | AK39: 0.3 | AL39: 0.3 | AM39: 0.3 | AN39: 0.3 | AO39: 0.3 | AP39: 0.3 | AQ39: 0.3 | AR39: 0.3 | AS39: 0.3 | AT39: 0.3 | AU39: 0.3 | AV39: 0.3 | AW39: 0.3 | AX39: 0.3 | AY39: 0.3 | AZ39: 0.3 | BA39: 0.3 | BB39: 0.3 | BC39: 0.3 | BD39: 0.3 | BE39: 0.3 | BF39: 0.3 | BG39: 0.3 | BH39: 0.3 | BI39: 0.3 | BJ39: 0.3 | BK39: 0.3 | BL39: 0.3 | BM39: 0.3 | BN39: 0.3 | BO39: 0.3 | BP39: 0.3 | BQ39: 0.3 | BR39: 0.3 | BS39: 0.3 | BT39: 0.3 | BU39: 0.3 | BV39: 0.3
A40: Tier 6 | B40: % | F40: 0.4 | G40: 0.4 | H40: 0.4 | I40: 0.4 | J40: 0.4 | K40: 0.4 | L40: 0.4 | M40: 0.4 | N40: 0.4 | O40: 0.4 | P40: 0.4 | Q40: 0.4 | R40: 0.4 | S40: 0.4 | T40: 0.4 | U40: 0.4 | V40: 0.4 | W40: 0.4 | X40: 0.4 | Y40: 0.4 | Z40: 0.4 | AA40: 0.4 | AB40: 0.4 | AC40: 0.4 | AD40: 0.4 | AE40: 0.4 | AF40: 0.4 | AG40: 0.4 | AH40: 0.4 | AI40: 0.4 | AJ40: 0.4 | AK40: 0.4 | AL40: 0.4 | AM40: 0.4 | AN40: 0.4 | AO40: 0.4 | AP40: 0.4 | AQ40: 0.4 | AR40: 0.4 | AS40: 0.4 | AT40: 0.4 | AU40: 0.4 | AV40: 0.4 | AW40: 0.4 | AX40: 0.4 | AY40: 0.4 | AZ40: 0.4 | BA40: 0.4 | BB40: 0.4 | BC40: 0.4 | BD40: 0.4 | BE40: 0.4 | BF40: 0.4 | BG40: 0.4 | BH40: 0.4 | BI40: 0.4 | BJ40: 0.4 | BK40: 0.4 | BL40: 0.4 | BM40: 0.4 | BN40: 0.4 | BO40: 0.4 | BP40: 0.4 | BQ40: 0.4 | BR40: 0.4 | BS40: 0.4 | BT40: 0.4 | BU40: 0.4 | BV40: 0.4
A42: Royalty on first threshold | B42: AUD/t | D42: =D29*D35 -> 7 | E42: =E29*E35 -> 7 | F42: =F29*F35 -> 7 | G42: =G29*G35 -> 7 | H42: =H29*H35 -> 7 | I42: =I29*I35 -> 7 | J42: =J29*J35 -> 7 | K42: =K29*K35 -> 7 | ... BV42: =BV29*BV35 -> 7
A43: Royalty up to second threshold | B43: AUD/t | D43: =D42+(D30-D29)*D36 -> 13.25 | E43: =E42+(E30-E29)*E36 -> 13.25 | F43: =F42+(F30-F29)*F36 -> 13.25 | G43: =G42+(G30-G29)*G36 -> 13.25 | H43: =H42+(H30-H29)*H36 -> 13.25 | I43: =I42+(I30-I29)*I36 -> 13.25 | J43: =J42+(J30-J29)*J36 -> 13.25 | K43: =K42+(K30-K29)*K36 -> 13.25 | ... BV43: =BV42+(BV30-BV29)*BV36 -> 13.25
A44: Royalty up to third threshold | B44: AUD/t | F44: =F43+(F31-F30)*F37 -> 17 | G44: =G43+(G31-G30)*G37 -> 17 | H44: =H43+(H31-H30)*H37 -> 17 | I44: =I43+(I31-I30)*I37 -> 17 | J44: =J43+(J31-J30)*J37 -> 17 | K44: =K43+(K31-K30)*K37 -> 17 | L44: =L43+(L31-L30)*L37 -> 17 | M44: =M43+(M31-M30)*M37 -> 17 | ... BV44: =BV43+(BV31-BV30)*BV37 -> 17
A45: Royalty up to fourth threshold | B45: AUD/t | F45: =F44+(F32-F31)*F38 -> 27 | G45: =G44+(G32-G31)*G38 -> 27 | H45: =H44+(H32-H31)*H38 -> 27 | I45: =I44+(I32-I31)*I38 -> 27 | J45: =J44+(J32-J31)*J38 -> 27 | K45: =K44+(K32-K31)*K38 -> 27 | L45: =L44+(L32-L31)*L38 -> 27 | M45: =M44+(M32-M31)*M38 -> 27 | ... BV45: =BV44+(BV32-BV31)*BV38 -> 27
A46: Royalty up to fifth threshold | B46: AUD/t | F46: =F45+(F33-F32)*F39 -> 49.5 | G46: =G45+(G33-G32)*G39 -> 49.5 | H46: =H45+(H33-H32)*H39 -> 49.5 | I46: =I45+(I33-I32)*I39 -> 49.5 | J46: =J45+(J33-J32)*J39 -> 49.5 | K46: =K45+(K33-K32)*K39 -> 49.5 | L46: =L45+(L33-L32)*L39 -> 49.5 | M46: =M45+(M33-M32)*M39 -> 49.5 | ... BV46: =BV45+(BV33-BV32)*BV39 -> 49.5
A49: AUD CPI | B49: % | D49: 0.01 | E49: 0.01 | F49: 0.01 | G49: 0.01 | H49: 0.01 | I49: 0.01 | J49: 0.0265 | K49: 0.0265 | L49: 0.0265 | M49: 0.0265 | N49: 0.0265 | O49: 0.0265 | P49: 0.0265 | Q49: 0.0265 | R49: 0.0265 | S49: 0.0265 | T49: 0.0265 | U49: 0.0265 | V49: 0.0265 | W49: 0.0265 | X49: 0.0265 | Y49: 0.0265 | Z49: 0.0265 | AA49: 0.0265 | AB49: 0.0265 | AC49: 0.0265 | AD49: 0.0265 | AE49: 0.0265 | AF49: 0.0265 | AG49: 0.0265 | AH49: 0.0265 | AI49: 0.0265 | AJ49: 0.0265 | AK49: 0.0265 | AL49: 0.0265 | AM49: 0.0265 | AN49: 0.0265 | AO49: 0.0265 | AP49: 0.0265 | AQ49: 0.0265 | AR49: 0.0265 | AS49: 0.0265 | AT49: 0.0265 | AU49: 0.0265 | AV49: 0.0265 | AW49: 0.0265 | AX49: 0.0265 | AY49: 0.0265 | AZ49: 0.0265 | BA49: 0.0265 | BB49: 0.0265 | BC49: 0.0265 | BD49: 0.0265 | BE49: 0.0265 | BF49: 0.0265 | BG49: 0.0265 | BH49: 0.0265 | BI49: 0.0265 | BJ49: 0.0265 | BK49: 0.0265 | BL49: 0.0265 | BM49: 0.0265 | BN49: 0.0265 | BO49: 0.0265 | BP49: 0.0265 | BQ49: 0.0265 | BR49: 0.0265 | BS49: 0.0265 | BT49: 0.0265 | BU49: 0.0265 | BV49: 0.0265
A52: Flood Rate
A53: 0
...

Sheet Analysis
C1: 2021Act | D1: 2022Act | E1: 2023Act | F1: 2024Act | G1: 2025Act | H1: 2026FYF | I1: 2027 | J1: =I1+1 -> 2028 | K1: =J1+1 -> 2029 | L1: =K1+1 -> 2030 | M1: =L1+1 -> 2031 | N1: =M1+1 -> 2032 | O1: =N1+1 -> 2033 | P1: =O1+1 -> 2034 | Q1: =P1+1 -> 2035 | ... AH1: =AG1+1 -> 2052
A2: FOR cash cost/t
A3: Springbok Coal Complex | B3: AUD/t | C3: ='Historical Performance'!D117 -> 134.97782 | D3: ='Historical Performance'!E117 -> 144.9523 | E3: ='Historical Performance'!F117 -> 136.08293 | F3: ='Historical Performance'!G117 -> 145.64931 | G3: ='Historical Performance'!H117 -> 168.45908 | H3: ='Historical Performance'!I117 -> 147.37336 | I3: =IF(Springbok!D90=0,NA(),Springbok!D90) -> 155.73261 | J3: =IF(Springbok!E90=0,NA(),Springbok!E90) -> 154.91662 | K3: =IF(Springbok!F90=0,NA(),Springbok!F90) -> 149.10247 | L3: =IF(Springbok!G90=0,NA(),Springbok!G90) -> 143.58757 | M3: =IF(Springbok!H90=0,NA(),Springbok!H90) -> 144.30907 | N3: =IF(Springbok!I90=0,NA(),Springbok!I90) -> #N/A | O3: =IF(Springbok!J90=0,NA(),Springbok!J90) -> #N/A | P3: =IF(Springbok!K90=0,NA(),Springbok!K90) -> #N/A | ... AH3: =IF(Springbok!AC90=0,NA(),Springbok!AC90) -> #N/A
A4: Brave Blossom UG | B4: AUD/t | I4: =IF('Brave Blossom '!D90=0,NA(),'Brave Blossom '!D90) -> #N/A | J4: =IF('Brave Blossom '!E90=0,NA(),'Brave Blossom '!E90) -> #N/A | K4: =IF('Brave Blossom '!F90=0,NA(),'Brave Blossom '!F90) -> #N/A | L4: =IF('Brave Blossom '!G90=0,NA(),'Brave Blossom '!G90) -> #N/A | M4: =IF('Brave Blossom '!H90=0,NA(),'Brave Blossom '!H90) -> 1088.3876 | N4: =IF('Brave Blossom '!I90=0,NA(),'Brave Blossom '!I90) -> 1241.8899 | O4: =IF('Brave Blossom '!J90=0,NA(),'Brave Blossom '!J90) -> 120.40978 | P4: =IF('Brave Blossom '!K90=0,NA(),'Brave Blossom '!K90) -> 120.40978 | ... AH4: =IF('Brave Blossom '!AC90=0,NA(),'Brave Blossom '!AC90) -> #N/A
A6: Net Cashflow Before Tax
A7: Springbok Coal Complex | B7: AUDk | C7: ='Historical Performance'!D143 -> 522475.43 | D7: ='Historical Performance'!E143 -> 545821.27 | E7: ='Historical Performance'!F143 -> 482741.53 | F7: ='Historical Performance'!G143 -> 438805.48 | G7: ='Historical Performance'!H143 -> 351060.19 | H7: ='Historical Performance'!I143 -> 461475.23 | I7: =IF(Springbok!D118=0,NA(),Springbok!D118) -> 226119.3 | J7: =IF(Springbok!E118=0,NA(),Springbok!E118) -> 287082.17 | K7: =IF(Springbok!F118=0,NA(),Springbok!F118) -> 379815.77 | L7: =IF(Springbok!G118=0,NA(),Springbok!G118) -> 374686.35 | M7: =IF(Springbok!H118=0,NA(),Springbok!H118) -> 325082.09 | N7: =IF(Springbok!I118=0,NA(),Springbok!I118) -> -895000 | O7: =IF(Springbok!J118=0,NA(),Springbok!J118) -> #N/A | P7: =IF(Springbok!K118=0,NA(),Springbok!K118) -> #N/A | ... AH7: =IF(Springbok!AC118=0,NA(),Springbok!AC118) -> #N/A
A8: Brave Blossom UG | B8: AUDk | I8: =IF('Brave Blossom '!D118=0,NA(),'Brave Blossom '!D118) -> #N/A | J8: =IF('Brave Blossom '!E118=0,NA(),'Brave Blossom '!E118) -> #N/A | K8: =IF('Brave Blossom '!F118=0,NA(),'Brave Blossom '!F118) -> #N/A | L8: =IF('Brave Blossom '!G118=0,NA(),'Brave Blossom '!G118) -> #N/A | M8: =IF('Brave Blossom '!H118=0,NA(),'Brave Blossom '!H118) -> -76108.799 | N8: =IF('Brave Blossom '!I118=0,NA(),'Brave Blossom '!I118) -> -173927.55 | O8: =IF('Brave Blossom '!J118=0,NA(),'Brave Blossom '!J118) -> 452810.4 | P8: =IF('Brave Blossom '!K118=0,NA(),'Brave Blossom '!K118) -> 438582.14 | ... AH8: =IF('Brave Blossom '!AC118=0,NA(),'Brave Blossom '!AC118) -> -91684.509
A10: Net Cashflow Before Tax Combined
A11: Springbok Coal Complex + Brave Blossom UG - Project | B11: AUDk | C11: =C7 -> 522475.43 | D11: =D7 -> 545821.27 | E11: =E7 -> 482741.53 | F11: =F7 -> 438805.48 | G11: =G7 -> 351060.19 | H11: =H7 -> 461475.23 | I11: ='Brave Blossom '!D118+Springbok!D118 -> 226119.3 | J11: ='Brave Blossom '!E118+Springbok!E118 -> 287082.17 | K11: ='Brave Blossom '!F118+Springbok!F118 -> 379815.77 | L11: ='Brave Blossom '!G118+Springbok!G118 -> 374686.35 | M11: ='Brave Blossom '!H118+Springbok!H118 -> 248973.3 | N11: ='Brave Blossom '!I118+Springbok!I118 -> -1068927.6 | O11: ='Brave Blossom '!J118+Springbok!J118 -> 452810.4 | P11: ='Brave Blossom '!K118+Springbok!K118 -> 438582.14 | ... AH11: ='Brave Blossom '!AC118+Springbok!AC118 -> -91684.509
A13: Attributable Net Cashflow After Tax Combined
A14: Brave Blossom UG - Project + Springbok Coal Complex | B14: AUDk | C14: ='Historical Performance'!D148 -> 210281.47 | D14: ='Historical Performance'!E148 -> 210309.36 | E14: ='Historical Performance'!F148 -> 185079.12 | F14: ='Historical Performance'!G148 -> 170008.61 | G14: ='Historical Performance'!H148 -> 136101.95 | H14: ='Historical Performance'!I148 -> 178993.73 | I14: ='Brave Blossom '!D123+Springbok!D123 -> 87216.159 | J14: ='Brave Blossom '!E123+Springbok!E123 -> 115050.57 | K14: ='Brave Blossom '!F123+Springbok!F123 -> 162597.51 | L14: ='Brave Blossom '!G123+Springbok!G123 -> 163167.12 | M14: ='Brave Blossom '!H123+Springbok!H123 -> 106616.68 | N14: ='Brave Blossom '!I123+Springbok!I123 -> -641356.53 | O14: ='Brave Blossom '!J123+Springbok!J123 -> 181632.97 | P14: ='Brave Blossom '!K123+Springbok!K123 -> 176108.39 | ... AH14: ='Brave Blossom '!AC123+Springbok!AC123 -> -55010.705
A15: All | B15: AUDk | I15: ='Brave Blossom '!D123+Springbok!D123+'OC Clean'!D125 -> 87216.159 | J15: ='Brave Blossom '!E123+Springbok!E123+'OC Clean'!E125 -> 115050.57 | K15: ='Brave Blossom '!F123+Springbok!F123+'OC Clean'!F125 -> 162597.51 | L15: ='Brave Blossom '!G123+Springbok!G123+'OC Clean'!G125 -> 163167.12 | M15: ='Brave Blossom '!H123+Springbok!H123+'OC Clean'!H125 -> 106616.68 | N15: ='Brave Blossom '!I123+Springbok!I123+'OC Clean'!I125 -> -641356.53 | O15: ='Brave Blossom '!J123+Springbok!J123+'OC Clean'!J125 -> 181632.97 | P15: ='Brave Blossom '!K123+Springbok!K123+'OC Clean'!K125 -> 176108.39 | ... AH15: ='Brave Blossom '!AC123+Springbok!AC123+'OC Clean'!AC125 -> -55010.705
A17: Discounted Cashflow After Tax Combined
A18: Brave Blossom UG - Project + Springbok Coal Complex | B18: AUDk | C18: =C14 -> 210281.47 | D18: =D14 -> 210309.36 | E18: =E14 -> 185079.12 | F18: =F14 -> 170008.61 | G18: =G14 -> 136101.95 | H18: =H14 -> 178993.73 | I18: ='Brave Blossom '!D124+Springbok!D124 -> 83923.788 | J18: ='Brave Blossom '!E124+Springbok!E124 -> 170844.85 | K18: ='Brave Blossom '!F124+Springbok!F124 -> 223564.71 | L18: ='Brave Blossom '!G124+Springbok!G124 -> 207729.54 | M18: ='Brave Blossom '!H124+Springbok!H124 -> 125680.24 | N18: ='Brave Blossom '!I124+Springbok!I124 -> -700031.55 | O18: ='Brave Blossom '!J124+Springbok!J124 -> 183564.64 | P18: ='Brave Blossom '!K124+Springbok!K124 -> 164797.5 | ... AH18: ='Brave Blossom '!AC124+Springbok!AC124 -> -12882.205
A19: Springbok (Base Case) | B19: AUDk | I19: =Springbok!D124 -> 83923.788 | J19: =Springbok!E124 -> 170844.85 | K19: =Springbok!F124 -> 223564.71 | L19: =Springbok!G124 -> 207729.54 | M19: =Springbok!H124 -> 179510.69 | N19: =Springbok!I124 -> -586127.88 | O19: =Springbok!J124 -> 0 | P19: =Springbok!K124 -> 0 | ... AH19: =Springbok!AC124 -> 0
A21: Cumulative Discounted Cashflow After Tax Combined
A22: Brave Blossom UG - Project + Springbok Coal Complex | B22: AUDk | I22: =SUM($I18) -> 83923.788 | J22: =SUM($I18:J18) -> 254768.64 | K22: =SUM($I18:K18) -> 478333.34 | L22: =SUM($I18:L18) -> 686062.89 | M22: =SUM($I18:M18) -> 811743.13 | N22: =SUM($I18:N18) -> 111711.58 | O22: =SUM($I18:O18) -> 295276.21 | P22: =SUM($I18:P18) -> 460073.72 | Q22: =SUM($I18:Q18) -> 607881.55 | ... AH22: =SUM($I18:AH18) -> 1669665.3
A23: Springbok (Base Case) | B23: AUDk | I23: =SUM($H19:I19) -> 83923.788 | J23: =SUM($H19:J19) -> 254768.64 | K23: =SUM($H19:K19) -> 478333.34 | L23: =SUM($H19:L19) -> 686062.89 | M23: =SUM($H19:M19) -> 865573.58 | N23: =SUM($H19:N19) -> 279445.69 | O23: =SUM($H19:O19) -> 279445.69 | P23: =SUM($H19:P19) -> 279445.69 | ... AH23: =SUM($H19:AH19) -> 279445.69
A24: Brave Blossom UG Project Standalone | B24: AUDk | I24: =SUM('Brave Blossom '!$D$124:'Brave Blossom '!D124) -> 0 | J24: =SUM('Brave Blossom '!$D$124:'Brave Blossom '!E124) -> 0 | K24: =SUM('Brave Blossom '!$D$124:'Brave Blossom '!F124) -> 0 | L24: =SUM('Brave Blossom '!$D$124:'Brave Blossom '!G124) -> 0 | M24: =SUM('Brave Blossom '!$D$124:'Brave Blossom '!H124) -> -53830.445 | N24: =SUM('Brave Blossom '!$D$124:'Brave Blossom '!I124) -> -167734.12 | O24: =SUM('Brave Blossom '!$D$124:'Brave Blossom '!J124) -> 15830.519 | P24: =SUM('Brave Blossom '!$D$124:'Brave Blossom '!K124) -> 180628.02 | ... AH24: =SUM('Brave Blossom '!$D$124:'Brave Blossom '!AC124) -> 1390219.6

Sheet List
A1: Owner/operate | B1: 7on7off | C1: 4 | D1: Max Quality | E1: SIS | F1: Yes | G1: Preventative Maintenance | H1: Maintain
A2: Contract | B2: 5on2off | C2: 3 | D2: Max Quantity | E2: UIS | F2: No | G2: Corrective Maintenance | H2: Increase 10%
B3: Other | C3: 2 | H3: Decrease 10%
C4: 1

Sheet Summary
A1: INPUTS FOR REVENUE GRAPH | D1: 2022 | E1: 2023 | F1: 2024 | G1: 2025 | H1: 2026
D2: 2022 A | E2: 2023 A | F2: 2024 A | G2: 2025 A | H2: 2026 FYF | I2: 2027 | J2: 2028 | K2: 2029 | L2: 2030 | M2: 2031 | N2: 2032 | O2: 2033 | P2: 2034 | Q2: 2035 | R2: 2036 | S2: 2037 | T2: 2038 | U2: 2039 | V2: 2040 | W2: 2041 | X2: 2042 | Y2: 2043 | Z2: 2044 | AA2: 2045 | AB2: 2046 | AC2: 2047 | AD2: 2048 | AE2: 2049 | AF2: 2050 | AG2: 2051 | AH2: 2052
B3: Sales Revenue | C3: AUD M | D3: ='Historical Performance'!E29/1000 -> 1678.1498 | E3: ='Historical Performance'!F29/1000 -> 2073.4218 | F3: ='Historical Performance'!G29/1000 -> 1959.2335 | G3: ='Historical Performance'!H29/1000 -> 1596.6324 | H3: ='Historical Performance'!I29/1000 -> 2003.9783 | I3: =IF(I14>0,(Springbok!D62)/1000,0) -> 1209.8149 | J3: =IF(J14>0,(Springbok!E62)/1000,0) -> 1319.7575 | K3: =IF(K14>0,(Springbok!F62)/1000,0) -> 1395.4746 | L3: =IF(L14>0,(Springbok!G62)/1000,0) -> 1344.3738 | M3: =IF(M14>0,(Springbok!H62)/1000,0) -> 1222.5303 | N3: =IF(N14>0,(Springbok!I62)/1000,0) -> 0 | O3: =IF(O14>0,(Springbok!J62)/1000,0) -> 0 | P3: =IF(P14>0,(Springbok!K62)/1000,0) -> 0 | ... AH3: =IF(AH14>0,(Springbok!AC62)/1000,0) -> 0
B4: Average Realisation A$ (Ex-Mine) | C4: AUD/t | D4: ='Historical Performance'!E30 -> 502.98492 | E4: ='Historical Performance'!F30 -> 505.24374 | F4: ='Historical Performance'!G30 -> 464.21175 | G4: ='Historical Performance'!H30 -> 431.39635 | H4: ='Historical Performance'!I30 -> 470.0855 | I4: =IF(I14>0,(Springbok!D34*Springbok!D63)/Summary!I14,0) -> 347.82609 | J4: =IF(J14>0,(Springbok!E34*Springbok!E63)/Summary!J14,0) -> 347.82609 | K4: =IF(K14>0,(Springbok!F34*Springbok!F63)/Summary!K14,0) -> 347.82609 | L4: =IF(L14>0,(Springbok!G34*Springbok!G63)/Summary!L14,0) -> 347.82609 | M4: =IF(M14>0,(Springbok!H34*Springbok!H63)/Summary!M14,0) -> 347.82609 | N4: =IF(N14>0,(Springbok!I34*Springbok!I63)/Summary!N14,0) -> 0 | O4: =IF(O14>0,(Springbok!J34*Springbok!J63)/Summary!O14,0) -> 0 | P4: =IF(P14>0,(Springbok!K34*Springbok!K63)/Summary!P14,0) -> 0 | ... AH4: =IF(AH14>0,(Springbok!AC34*Springbok!AC63)/Summary!AH14,0) -> 0
B6: Direct Mining Cost | C6: AUD/t | D6: ='Historical Performance'!E78/'Historical Performance'!E20 -> 104.83961 | E6: ='Historical Performance'!F78/'Historical Performance'!F20 -> 101.45796 | F6: ='Historical Performance'!G78/'Historical Performance'!G20 -> 109.42968 | G6: ='Historical Performance'!H78/'Historical Performance'!H20 -> 136.99268 | H6: ='Historical Performance'!I78/'Historical Performance'!I20 -> 110.85684 | I6: =IF(I14>0,(Springbok!D70+Springbok!D73+Springbok!D75+Springbok!D78)/I14,0) -> 115.96569 | J6: =IF(J14>0,(Springbok!E70+Springbok!E73+Springbok!E75+Springbok!E78)/J14,0) -> 117.2813 | K6: =IF(K14>0,(Springbok!F70+Springbok!F73+Springbok!F75+Springbok!F78)/K14,0) -> 112.73986 | L6: =IF(L14>0,(Springbok!G70+Springbok!G73+Springbok!G75+Springbok!G78)/L14,0) -> 106.38174 | M6: =IF(M14>0,(Springbok!H70+Springbok!H73+Springbok!H75+Springbok!H78)/M14,0) -> 104.80828 | N6: =IF(N14>0,(Springbok!I70+Springbok!I73+Springbok!I75+Springbok!I78)/N14,0) -> 0 | O6: =IF(O14>0,(Springbok!J70+Springbok!J73+Springbok!J75+Springbok!J78)/O14,0) -> 0 | P6: =IF(P14>0,(Springbok!K70+Springbok!K73+Springbok!K75+Springbok!K78)/P14,0) -> 0 | ... AH6: =IF(AH14>0,(Springbok!AC70+Springbok!AC73+Springbok!AC75+Springbok!AC78)/AH14,0) -> 0
B7: CHPP Cash Cost | C7: AUD/t | D7: ='Historical Performance'!E89/'Historical Performance'!E20 -> 24.805187 | E7: ='Historical Performance'!F89/'Historical Performance'!F20 -> 19.601723 | F7: ='Historical Performance'!G89/'Historical Performance'!G20 -> 20.124839 | G7: ='Historical Performance'!H89/'Historical Performance'!H20 -> 27.8445 | H7: ='Historical Performance'!I89/'Historical Performance'!I20 -> 18.753983 | I7: =IF(I14>0,(Springbok!D82)/Summary!I14,0) -> 19.929176 | J7: =IF(J14>0,(Springbok!E82)/Summary!J14,0) -> 19.450165 | K7: =IF(K14>0,(Springbok!F82)/Summary!K14,0) -> 19.164162 | L7: =IF(L14>0,(Springbok!G82)/Summary!L14,0) -> 19.353649 | M7: =IF(M14>0,(Springbok!H82)/Summary!M14,0) -> 19.86937 | N7: =IF(N14>0,(Springbok!I82)/Summary!N14,0) -> 0 | O7: =IF(O14>0,(Springbok!J82)/Summary!O14,0) -> 0 | P7: =IF(P14>0,(Springbok!K82)/Summary!P14,0) -> 0 | ... AH7: =IF(AH14>0,(Springbok!AC82)/Summary!AH14,0) -> 0
B8: Overhead & Indirect Cash Cost | C8: AUD/t | D8: ='Historical Performance'!E114/'Historical Performance'!E20 -> 19.845559 | E8: ='Historical Performance'!F114/'Historical Performance'!F20 -> 18.757798 | F8: ='Historical Performance'!G114/'Historical Performance'!G20 -> 17.171115 | G8: ='Historical Performance'!H114/'Historical Performance'!H20 -> 20.936954 | H8: ='Historical Performance'!I114/'Historical Performance'!I20 -> 17.78253 | I8: =IF(I14>0,(Springbok!D87)/Summary!I14,0) -> 19.837746 | J8: =IF(J14>0,(Springbok!E87)/Summary!J14,0) -> 18.185159 | K8: =IF(K14>0,(Springbok!F87)/Summary!K14,0) -> 17.19845 | L8: =IF(L14>0,(Springbok!G87)/Summary!L14,0) -> 17.852178 | M8: =IF(M14>0,(Springbok!H87)/Summary!M14,0) -> 19.631415 | N8: =IF(N14>0,(Springbok!I87)/Summary!N14,0) -> 0 | O8: =IF(O14>0,(Springbok!J87)/Summary!O14,0) -> 0 | P8: =IF(P14>0,(Springbok!K87)/Summary!P14,0) -> 0 | ... AH8: =IF(AH14>0,(Springbok!AC87)/Summary!AH14,0) -> 0
B9: Distribution (excluding Royalty) | C9: AUD/t | D9: ='Historical Performance'!E119/'Historical Performance'!E20 -> 109.19554 | E9: ='Historical Performance'!F119/'Historical Performance'!F20 -> 128.43743 | F9: ='Historical Performance'!G119/'Historical Performance'!G20 -> 96.736444 | G9: ='Historical Performance'!H119/'Historical Performance'!H20 -> 72.174756 | H9: ='Historical Performance'!I119/'Historical Performance'!I20 -> 83.85925 | I9: =IF(I14>0,(Springbok!D93+Springbok!D94)/Summary!I14,0) -> 34 | J9: =IF(J14>0,(Springbok!E93+Springbok!E94)/Summary!J14,0) -> 34 | K9: =IF(K14>0,(Springbok!F93+Springbok!F94)/Summary!K14,0) -> 24 | L9: =IF(L14>0,(Springbok!G93+Springbok!G94)/Summary!L14,0) -> 24 | M9: =IF(M14>0,(Springbok!H93+Springbok!H94)/Summary!M14,0) -> 24 | N9: =IF(N14>0,(Springbok!I93+Springbok!I94)/Summary!N14,0) -> 0 | O9: =IF(O14>0,(Springbok!J93+Springbok!J94)/Summary!O14,0) -> 0 | P9: =IF(P14>0,(Springbok!K93+Springbok!K94)/Summary!P14,0) -> 0 | ... AH9: =IF(AH14>0,(Springbok!AC93+Springbok!AC94)/Summary!AH14,0) -> 0
B10: Other Costs (Carbon) | C10: AUD/t | D10: ='Historical Performance'!E131/'Historical Performance'!E20 -> 0 | E10: ='Historical Performance'!F131/'Historical Performance'!F20 -> 0 | F10: ='Historical Performance'!G131/'Historical Performance'!G20 -> 2.2856574 | G10: ='Historical Performance'!H131/'Historical Performance'!H20 -> 2.4227514 | H10: ='Historical Performance'!I131/'Historical Performance'!I20 -> 6.2401719 | I10: =IF(I14>0,(Springbok!D106)/I14,0) -> 2.8063866 | J10: =IF(J14>0,(Springbok!E106)/J14,0) -> 3.7689627 | K10: =IF(K14>0,(Springbok!F106)/K14,0) -> 4.8295072 | L10: =IF(L14>0,(Springbok!G106)/L14,0) -> 6.2669801 | M10: =IF(M14>0,(Springbok!H106)/M14,0) -> 8.1149314 | N10: =IF(N14>0,(Springbok!I106)/N14,0) -> 0 | O10: =IF(O14>0,(Springbok!J106)/O14,0) -> 0 | P10: =IF(P14>0,(Springbok!K106)/P14,0) -> 0 | ... AH10: =IF(AH14>0,(Springbok!AC106)/AH14,0) -> 0
B11: Royalty - Government Export | C11: AUD/t | D11: ='Historical Performance'!E120/'Historical Performance'!E20 -> 51.826537 | E11: ='Historical Performance'!F120/'Historical Performance'!F20 -> 98.144248 | F11: ='Historical Performance'!G120/'Historical Performance'!G20 -> 91.18152 | G11: ='Historical Performance'!H120/'Historical Performance'!H20 -> 84.983637 | H11: ='Historical Performance'!I120/'Historical Performance'!I20 -> 96.567101 | I11: =IF(I14>0,(Springbok!D95)/Summary!I14,0) -> 61.92181 | J11: =IF(J14>0,(Springbok!E95)/Summary!J14,0) -> 63.741704 | K11: =IF(K14>0,(Springbok!F95)/Summary!K14,0) -> 67.494049 | L11: =IF(L14>0,(Springbok!G95)/Summary!L14,0) -> 69.233218 | M11: =IF(M14>0,(Springbok!H95)/Summary!M14,0) -> 70.933105 | N11: =IF(N14>0,(Springbok!I95)/Summary!N14,0) -> 0 | O11: =IF(O14>0,(Springbok!J95)/Summary!O14,0) -> 0 | P11: =IF(P14>0,(Springbok!K95)/Summary!P14,0) -> 0 | ... AH11: =IF(AH14>0,(Springbok!AC95)/Summary!AH14,0) -> 0
B14: Total Sales Vol | I14: =Springbok!D34 -> 3478.2177 | J14: =Springbok!E34 -> 3794.3029 | K14: =Springbok!F34 -> 4011.9895 | L14: =Springbok!G34 -> 3865.0746 | M14: =Springbok!H34 -> 3514.7746 | N14: =Springbok!I34 -> 0 | O14: =Springbok!J34 -> 0 | P14: =Springbok!K34 -> 0 | ... AH14: =Springbok!AC34 -> 0
B44: Project Margin Analysis
D45: 2031 | E45: 2032 | F45: 2033 | G45: 2034 | H45: 2035 | I45: 2036 | J45: 2037 | K45: 2038 | L45: 2039 | M45: 2040 | N45: 2041 | O45: 2042 | P45: 2043 | Q45: 2044 | R45: 2045 | S45: 2046 | T45: 2047 | U45: 2048 | V45: 2049 | W45: 2050
B46: Sales Revenue | C46: AUD M | D46: =IF(D57>0,('Brave Blossom '!H62)/1000,0) -> 24.925273 | E46: =IF(E57>0,('Brave Blossom '!I62)/1000,0) -> 49.850546 | F46: =IF(F57>0,('Brave Blossom '!J62)/1000,0) -> 1652.479 | G46: =IF(G57>0,('Brave Blossom '!K62)/1000,0) -> 1652.479 | H46: =IF(H57>0,('Brave Blossom '!L62)/1000,0) -> 1652.479 | I46: =IF(I57>0,('Brave Blossom '!M62)/1000,0) -> 1652.479 | J46: =IF(J57>0,('Brave Blossom '!N62)/1000,0) -> 1652.479 | K46: =IF(K57>0,('Brave Blossom '!O62)/1000,0) -> 1652.479 | ... W46: =IF(W57>0,('Brave Blossom '!AA62)/1000,0) -> 1581.8574
B47: Average Realisation A$ (Ex-Mine) | C47: AUD/t | D47: =IF(D57>0,('Brave Blossom '!H34*'Brave Blossom '!H63)/D57,0) -> 306.08696 | E47: =IF(E57>0,('Brave Blossom '!I34*'Brave Blossom '!I63)/E57,0) -> 306.08696 | F47: =IF(F57>0,('Brave Blossom '!J34*'Brave Blossom '!J63)/F57,0) -> 306.08696 | G47: =IF(G57>0,('Brave Blossom '!K34*'Brave Blossom '!K63)/G57,0) -> 306.08696 | H47: =IF(H57>0,('Brave Blossom '!L34*'Brave Blossom '!L63)/H57,0) -> 306.08696 | I47: =IF(I57>0,('Brave Blossom '!M34*'Brave Blossom '!M63)/I57,0) -> 306.08696 | J47: =IF(J57>0,('Brave Blossom '!N34*'Brave Blossom '!N63)/J57,0) -> 306.08696 | K47: =IF(K57>0,('Brave Blossom '!O34*'Brave Blossom '!O63)/K57,0) -> 306.08696 | ... W47: =IF(W57>0,('Brave Blossom '!AA34*'Brave Blossom '!AA63)/W57,0) -> 306.08696
B49: Direct Mining Cost | C49: AUD/t | D49: =IF(D57>0,('Brave Blossom '!H70+'Brave Blossom '!H73+'Brave Blossom '!H75+'Brave Blossom '!H78)/D57,0) -> 822.99219 | E49: =IF(E57>0,('Brave Blossom '!I70+'Brave Blossom '!I73+'Brave Blossom '!I75+'Brave Blossom '!I78)/E57,0) -> 675.62997 | F49: =IF(F57>0,('Brave Blossom '!J70+'Brave Blossom '!J73+'Brave Blossom '!J75+'Brave Blossom '!J78)/F57,0) -> 89.953811 | G49: =IF(G57>0,('Brave Blossom '!K70+'Brave Blossom '!K73+'Brave Blossom '!K75+'Brave Blossom '!K78)/G57,0) -> 89.953811 | H49: =IF(H57>0,('Brave Blossom '!L70+'Brave Blossom '!L73+'Brave Blossom '!L75+'Brave Blossom '!L78)/H57,0) -> 89.953811 | I49: =IF(I57>0,('Brave Blossom '!M70+'Brave Blossom '!M73+'Brave Blossom '!M75+'Brave Blossom '!M78)/I57,0) -> 89.953811 | J49: =IF(J57>0,('Brave Blossom '!N70+'Brave Blossom '!N73+'Brave Blossom '!N75+'Brave Blossom '!N78)/J57,0) -> 89.953811 | K49: =IF(K57>0,('Brave Blossom '!O70+'Brave Blossom '!O73+'Brave Blossom '!O75+'Brave Blossom '!O78)/K57,0) -> 89.953811 | ... W49: =IF(W57>0,('Brave Blossom '!AA70+'Brave Blossom '!AA73+'Brave Blossom '!AA75+'Brave Blossom '!AA78)/W57,0) -> 77.321981
B50: CHPP Cash Cost | C50: AUD/t | D50: =IF(D57>0,('Brave Blossom '!H82)/D57,0) -> 265.39536 | E50: =IF(E57>0,('Brave Blossom '!I82)/E57,0) -> 142.59351 | F50: =IF(F57>0,('Brave Blossom '!J82)/F57,0) -> 17.675167 | G50: =IF(G57>0,('Brave Blossom '!K82)/G57,0) -> 17.675167 | H50: =IF(H57>0,('Brave Blossom '!L82)/H57,0) -> 17.675167 | I50: =IF(I57>0,('Brave Blossom '!M82)/I57,0) -> 17.675167 | J50: =IF(J57>0,('Brave Blossom '!N82)/J57,0) -> 17.675167 | K50: =IF(K57>0,('Brave Blossom '!O82)/K57,0) -> 17.675167 | ... W50: =IF(W57>0,('Brave Blossom '!AA82)/W57,0) -> 13.970588
B51: Overhead & Indirect Cash Cost | C51: AUD/t | D51: =IF(D57>0,('Brave Blossom '!H87)/D57,0) -> 0 | E51: =IF(E57>0,('Brave Blossom '!I87)/E57,0) -> 423.66637 | F51: =IF(F57>0,('Brave Blossom '!J87)/F57,0) -> 12.780798 | G51: =IF(G57>0,('Brave Blossom '!K87)/G57,0) -> 12.780798 | H51: =IF(H57>0,('Brave Blossom '!L87)/H57,0) -> 12.780798 | I51: =IF(I57>0,('Brave Blossom '!M87)/I57,0) -> 12.780798 | J51: =IF(J57>0,('Brave Blossom '!N87)/J57,0) -> 12.780798 | K51: =IF(K57>0,('Brave Blossom '!O87)/K57,0) -> 12.780798 | ... W51: =IF(W57>0,('Brave Blossom '!AA87)/W57,0) -> 13.351393
B52: Distribution (excluding Royalty) | C52: AUD/t | D52: =IF(D57>0,('Brave Blossom '!H93+'Brave Blossom '!H94)/D57,0) -> 22 | E52: =IF(E57>0,('Brave Blossom '!I93+'Brave Blossom '!I94)/E57,0) -> 22 | F52: =IF(F57>0,('Brave Blossom '!J93+'Brave Blossom '!J94)/F57,0) -> 22 | G52: =IF(G57>0,('Brave Blossom '!K93+'Brave Blossom '!K94)/G57,0) -> 22 | H52: =IF(H57>0,('Brave Blossom '!L93+'Brave Blossom '!L94)/H57,0) -> 22 | I52: =IF(I57>0,('Brave Blossom '!M93+'Brave Blossom '!M94)/I57,0) -> 22 | J52: =IF(J57>0,('Brave Blossom '!N93+'Brave Blossom '!N94)/J57,0) -> 22 | K52: =IF(K57>0,('Brave Blossom '!O93+'Brave Blossom '!O94)/K57,0) -> 22 | ... W52: =IF(W57>0,('Brave Blossom '!AA93+'Brave Blossom '!AA94)/W57,0) -> 22
B53: Other Costs (Carbon) | C53: AUD/t | D53: =IF(D57>0,('Brave Blossom '!H106)/D57,0) -> 32.006641 | E53: =IF(E57>0,('Brave Blossom '!I106)/E57,0) -> 25.521351 | F53: =IF(F57>0,('Brave Blossom '!J106)/F57,0) -> 12.162797 | G53: =IF(G57>0,('Brave Blossom '!K106)/G57,0) -> 13.237092 | H53: =IF(H57>0,('Brave Blossom '!L106)/H57,0) -> 14.355784 | I53: =IF(I57>0,('Brave Blossom '!M106)/I57,0) -> 15.518871 | J53: =IF(J57>0,('Brave Blossom '!N106)/J57,0) -> 16.029423 | K53: =IF(K57>0,('Brave Blossom '!O106)/K57,0) -> 16.539975 | ... W53: =IF(W57>0,('Brave Blossom '!AA106)/W57,0) -> 27.306502
B54: Royalty - Government Export | C54: AUD/t | D54: =IF(D57>0,('Brave Blossom '!H95)/D57,0) -> 55.122407 | E54: =IF(E57>0,('Brave Blossom '!I95)/E57,0) -> 56.756758 | F54: =IF(F57>0,('Brave Blossom '!J95)/F57,0) -> 58.354186 | G54: =IF(G57>0,('Brave Blossom '!K95)/G57,0) -> 59.915375 | H54: =IF(H57>0,('Brave Blossom '!L95)/H57,0) -> 61.441005 | I54: =IF(I57>0,('Brave Blossom '!M95)/I57,0) -> 62.931754 | J54: =IF(J57>0,('Brave Blossom '!N95)/J57,0) -> 64.388291 | K54: =IF(K57>0,('Brave Blossom '!O95)/K57,0) -> 65.811283 | ... W54: =IF(W57>0,('Brave Blossom '!AA95)/W57,0) -> 80.503475
B57: Total Sales Vol | D57: ='Brave Blossom '!H34 -> 81.432 | E57: ='Brave Blossom '!I34 -> 162.864 | F57: ='Brave Blossom '!J34 -> 5398.724 | G57: ='Brave Blossom '!K34 -> 5398.724 | H57: ='Brave Blossom '!L34 -> 5398.724 | I57: ='Brave Blossom '!M34 -> 5398.724 | J57: ='Brave Blossom '!N34 -> 5398.724 | K57: ='Brave Blossom '!O34 -> 5398.724 | ... W57: ='Brave Blossom '!AA34 -> 5168

Sheet Historical Performance
B3: Springbok Historical Performance | D3: 2021 | E3: 2022 | F3: 2023 | G3: 2024 | H3: 2025 | I3: FYF 2026
B4: PRODUCTION
B6: Development Metres | C6: m | D6: 18870.2 | E6: 17655.26 | F6: 16276.64 | G6: 18887.5 | H6: 14092.9 | I6: 17185.127
B7: ROM Production (kt) | C7: kt | D7: 5835.1904 | E7: 5207.3246 | F7: 6111.2246 | G7: 6109.0595 | H7: 5344.0865 | I7: 5943.705
B8: Operations Yield (%) | C8: % | D8: 0.65000435 | E8: 0.65130403 | F8: 0.68333809 | G8: 0.67876629 | H8: 0.69406896 | I8: 0.72284587
B9: Actual Saleable Production (kt) | C9: kt | D9: 3809.402 | E9: 3336.382 | F9: 4103.805 | G9: 4220.56 | H9: 3701.08 | I9: 4263.008
B11: CHPP
B12: Primary Feed Tonnes | C12: kt | D12: 5860.5792 | E12: 5122.6183 | F12: 6005.5265 | G12: 6217.9871 | H12: 5332.4385 | I12: 5897.5339
B13: Bypass Tonnes | C13: kt | D13: 0 | E13: 0 | F13: 0 | G13: 0 | H13: 0 | I13: 0
B14: Plant Product Tonnes | C14: kt | D14: 3809.402 | E14: 3336.382 | F14: 4103.805 | G14: 4220.56 | H14: 3701.08 | I14: 4263.008
B15: CHPP Yield | C15: % | D15: =D14/(D12+D13) -> 0.65000435 | E15: =E14/(E12+E13) -> 0.65130403 | F15: =F14/(F12+F13) -> 0.68333809 | G15: =G14/(G12+G13) -> 0.67876629 | H15: =H14/(H12+H13) -> 0.69406896 | I15: =I14/(I12+I13) -> 0.72284587
B17: Marketing
B18: PHCC | C18: kt | D18: 3780.3109 | E18: 3235.0999 | F18: 3994.1917 | G18: 4189.5997 | H18: 3356.1213 | I18: 4262.4299
B19: 88% PHCC | C19: kt
B20: Total Sales | C20: kt | D20: =SUM(D18:D19) -> 3780.3109 | E20: =SUM(E18:E19) -> 3235.0999 | F20: =SUM(F18:F19) -> 3994.1917 | G20: =SUM(G18:G19) -> 4189.5997 | H20: =SUM(H18:H19) -> 3356.1213 | I20: =SUM(I18:I19) -> 4262.4299
B22: Realised Price
B23: PHCC | C23: USD/t | D23: 295 | E23: 360 | F23: 345 | G23: 310 | H23: 300 | I23: 315
B24: 88% PHCC | C24: USD/t
B25: Average Export Realised Price | C25: USD/t
B27: Total Revenue | C27: USDk | D27: =SUMPRODUCT(D18:D19,D23:D24) -> 1115191.7 | E27: =SUMPRODUCT(E18:E19,E23:E24) -> 1164636 | F27: =SUMPRODUCT(F18:F19,F23:F24) -> 1377996.1 | G27: =SUMPRODUCT(G18:G19,G23:G24) -> 1298775.9 | H27: =SUMPRODUCT(H18:H19,H23:H24) -> 1006836.4 | I27: =SUMPRODUCT(I18:I19,I23:I24) -> 1342665.4
B28: FX | C28: USD:AUD | D28: 0.743 | E28: 0.694 | F28: 0.6646 | G28: 0.6629 | H28: 0.6306 | I28: 0.67
B29: Total Revenue | C29: AUD | D29: =D27/D28 -> 1500931 | E29: =E27/E28 -> 1678149.8 | F29: =F27/F28 -> 2073421.8 | G29: =G27/G28 -> 1959233.5 | H29: =H27/H28 -> 1596632.4 | I29: =I27/I28 -> 2003978.3
B30: Average Realisation | C30: AUD/t | D30: =IFERROR(D29/D9,0) -> 394.00698 | E30: =IFERROR(E29/E9,0) -> 502.98492 | F30: =IFERROR(F29/F9,0) -> 505.24374 | G30: =IFERROR(G29/G9,0) -> 464.21175 | H30: =IFERROR(H29/H9,0) -> 431.39635 | I30: =IFERROR(I29/I9,0) -> 470.0855
B33: PIT TOP COSTS
B35: LABOUR
B36: Roster Labour | C36: AUDk | D36: 47056.114 | E36: 48060.789 | F36: 69060.911 | G36: 76942.993 | H36: 75336.191 | I36: 80032.977
B37: Non Rostered Overtime | C37: AUDk | D37: 1681.8503 | E37: 2500.8709 | F37: 4953.1897 | G37: 5809.7424 | H37: 4013.871 | I37: 3573.1287
B38: Bonus | C38: AUDk | D38: 8535.7186 | E38: 7634.122 | F38: 12511.045 | G38: 15141.554 | H38: 14736.528 | I38: 14811.072
B39: Oncosts | C39: AUDk | D39: 19564.521 | E39: 16288.213 | F39: 33977.427 | G39: 37669.483 | H39: 37114.405 | I39: 31006.633
B40: Supplementary Labour | C40: AUDk | D40: 41000.054 | E40: 50376.88 | F40: 51764.529 | G40: 56992.705 | H40: 61400.365 | I40: 81378.813
B41: Capitalised Labour | C41: AUDk | D41: 0 | E41: 0 | F41: 0 | G41: 0 | H41: 0 | I41: 0
B42: Labour Costs / Eq Saleable | C42: AUDk | D42: =SUM(D36:D41) -> 117838.26 | E42: =SUM(E36:E41) -> 124860.88 | F42: =SUM(F36:F41) -> 172267.1 | G42: =SUM(G36:G41) -> 192556.48 | H42: =SUM(H36:H41) -> 192601.36 | I42: =SUM(I36:I41) -> 210802.62
B44: REPAIRS/MAINTENANCE
B45: Electrical Parts | C45: AUDk | D45: 9965.8191 | E45: 11877.628 | F45: 14718.803 | G45: 15671.795 | H45: 15891.335 | I45: 13435.994
B46: Mechanical Parts | C46: AUDk | D46: 28328.866 | E46: 20948.204 | F46: 28955.942 | G46: 35206.732 | H46: 31237.773 | I46: 31457.78
B47: Major Rebuilds | C47: AUDk | D47: 26852.738 | E47: 24931.614 | F47: 25186.147 | G47: 31547.04 | H47: 39030.647 | I47: 34935.981
B48: Outside Mech/Elect Repairs | C48: AUDk | D48: 17235.525 | E48: 9755.3986 | F48: 15146.939 | G48: 18187.025 | H48: 15584.941 | I48: 12582.757
B49: Maintenance Agreements | C49: AUDk | D49: 3191.9474 | E49: 3217.5357 | F49: 4460.6962 | G49: 5460.6453 | H49: 4052.5299 | I49: 5494.2062
B50: Repairs/Maintenance / Eq Saleable | C50: AUDk | D50: =SUM(D45:D49) -> 85574.896 | E50: =SUM(E45:E49) -> 70730.381 | F50: =SUM(F45:F49) -> 88468.528 | G50: =SUM(G45:G49) -> 106073.24 | H50: =SUM(H45:H49) -> 105797.23 | I50: =SUM(I45:I49) -> 97906.719
B52: CONSUMABLES
...

Sheet Springbok Assumptions
B1: Current | C1: Proposed
A3: Roster - Longwall | B3: 7on7off | C3: 7on7off
A4: Roster - Development | B4: 7on7off | C4: 5on2off
A5: Roster - Outbye | B5: 7on7off | C5: 7on7off
A6: Development Miners | B6: 3 | C6: 4
A7: Gas Drainage Strategy | B7: SIS | C7: UIS
A8: Wash Strategy | B8: Max Quality | C8: Max Quality
A9: Progressive Rehabilitation | B9: Yes | C9: No
A10: Maintenance Strategy | B10: Preventative Maintenance | C10: Corrective Maintenance

Sheet Springbok
D1: 2 | E1: =+D1+1 -> 3 | F1: =+E1+1 -> 4 | G1: =+F1+1 -> 5 | H1: =+G1+1 -> 6 | I1: =+H1+1 -> 7 | J1: =+I1+1 -> 8 | K1: =+J1+1 -> 9 | L1: =+K1+1 -> 10 | ... AD1: =+AC1+1 -> 28
A2: Springbok Complex | D2: =Assumptions!J1 -> 2027 | E2: =D2+1 -> 2028 | F2: =E2+1 -> 2029 | G2: =F2+1 -> 2030 | H2: =G2+1 -> 2031 | I2: =H2+1 -> 2032 | J2: =I2+1 -> 2033 | K2: =J2+1 -> 2034 | L2: =K2+1 -> 2035 | ... AD2: =AC2+1 -> 2053 | AF2: Total | AH2: Valuation Summary
A3: Physicals | AH3: Net Present Value (AUDM) | AI3: =AF124/1000 -> 279.44569
V4: =V6*5.5*3.55*1.45 -> 0 | W4: =W6*5.5*3.55*1.45 -> 0 | Z4: =Z6*5.5*3.55*1.45 -> 0 | AA4: =AA6*5.5*3.55*1.45 -> 0 | AC4: =AC6*5.5*3.55*1.45 -> 0 | AD4: =AD6*5.5*3.55*1.45 -> 0
A5: Mining
A6: Development Metres | B6: m | D6: 9000 | E6: 15000 | F6: 15000 | G6: 8000 | H6: 2000 | I6: 0 | J6: 0 | K6: 0 | L6: 0 | M6: 0 | N6: 0 | O6: 0 | P6: 0 | Q6: 0 | R6: 0 | S6: 0 | T6: 0 | U6: 0 | V6: 0 | W6: 0 | X6: 0 | Y6: 0 | Z6: 0 | AA6: 0 | AB6: 0 | AC6: 0 | AD6: 0 | AF6: =SUM(D6:AD6) -> 49000 | AH6: Sensitivities Table
A7: Development Tonnes | B7: kt | D7: =(3*5.2*1.45*D6)/1000 -> 203.58 | E7: =(3*5.2*1.45*E6)/1000 -> 339.3 | F7: =(3*5.2*1.45*F6)/1000 -> 339.3 | G7: =(3*5.2*1.45*G6)/1000 -> 180.96 | H7: =(3*5.2*1.45*H6)/1000 -> 45.24 | I7: =(3*5.2*1.45*I6)/1000 -> 0 | J7: =(3*5.2*1.45*J6)/1000 -> 0 | K7: =(3*5.2*1.45*K6)/1000 -> 0 | ... AD7: =(3*5.2*1.45*AD6)/1000 -> 0 | AF7: =SUM(D7:AD7) -> 1108.38 | AH7: Sales Price | AI7: 0
A8: Longwall Tonnes | B8: kt | D8: 4987.7897 | E8: 5323.8386 | F8: 5648.744 | G8: 5587.808 | H8: 5200.6922 | K8: 0 | L8: 0 | M8: 0 | N8: 0 | O8: 0 | P8: 0 | Q8: 0 | R8: 0 | S8: 0 | T8: 0 | U8: 0 | V8: 0 | W8: 0 | X8: 0 | Y8: 0 | Z8: 0 | AA8: 0 | AB8: 0 | AC8: 0 | AD8: 0 | AF8: =SUM(D8:AD8) -> 26748.873 | AH8: Development Costs | AI8: 0
A9: Total ROM production | B9: kt | D9: =D7+D8 -> 5191.3697 | E9: =E7+E8 -> 5663.1386 | F9: =F7+F8 -> 5988.044 | G9: =G7+G8 -> 5768.768 | H9: =H7+H8 -> 5245.9322 | K9: =K7+K8 -> 0 | L9: =L7+L8 -> 0 | M9: =M7+M8 -> 0 | N9: =N7+N8 -> 0 | O9: =O7+O8 -> 0 | P9: =P7+P8 -> 0 | Q9: =Q7+Q8 -> 0 | R9: =R7+R8 -> 0 | ... AD9: =AD7+AD8 -> 0 | AF9: =SUM(C9:AD9) -> 27857.253 | AH9: Longwall Costs | AI9: 0
D10: =D6/D8 -> 1.8044065 | E10: =E6/E8 -> 2.8175159 | F10: =F6/F8 -> 2.6554576 | G10: =G6/G8 -> 1.4316884 | H10: =H6/H8 -> 0.38456419 | AH10: Outbye Costs | AI10: 0
A11: CHPP | AH11: Gas Drainage Costs | AI11: 0
A12: Primary Feed Tonnes | B12: kt | D12: =D9 -> 5191.3697 | E12: =E9 -> 5663.1386 | F12: =F9 -> 5988.044 | G12: =G9 -> 5768.768 | H12: =H9 -> 5245.9322 | I12: =I9 -> 0 | J12: =J9 -> 0 | K12: =K9 -> 0 | ... AD12: =AD9 -> 0 | AF12: =SUM(C12:AD12) -> 27857.253 | AH12: CHPP Costs | AI12: 0
A13: Bypass Tonnes | B13: kt | D13: 0 | E13: 0 | F13: 0 | G13: 0 | H13: 0 | I13: 0 | J13: 0 | K13: 0 | L13: 0 | M13: 0 | N13: 0 | O13: 0 | P13: 0 | Q13: 0 | R13: 0 | S13: 0 | T13: 0 | U13: 0 | V13: 0 | W13: 0 | X13: 0 | Y13: 0 | Z13: 0 | AA13: 0 | AB13: 0 | AC13: 0 | AD13: 0 | AF13: =SUM(C13:AD13) -> 0 | AH13: Total Overhead Costs | AI13: 0
A14: Plant Product Tonnes | B14: kt | D14: =D12*$C$15 -> 3478.2177 | E14: =E12*$C$15 -> 3794.3029 | F14: =F12*$C$15 -> 4011.9895 | G14: =G12*$C$15 -> 3865.0746 | H14: =H12*$C$15 -> 3514.7746 | I14: =I12*$C$15 -> 0 | J14: =J12*$C$15 -> 0 | K14: =K12*$C$15 -> 0 | ... AD14: =AD12*$C$15 -> 0 | AF14: =SUM(C14:AD14) -> 18664.359 | AH14: Total Capital Costs | AI14: 0
A15: CHPP Yield | B15: % | C15: 0.67 | D15: =IFERROR(D14/D12,0) -> 0.67 | E15: =IFERROR(E14/E12,0) -> 0.67 | F15: =IFERROR(F14/F12,0) -> 0.67 | G15: =IFERROR(G14/G12,0) -> 0.67 | H15: =IFERROR(H14/H12,0) -> 0.67 | I15: =IFERROR(I14/I12,0) -> 0 | J15: =IFERROR(J14/J12,0) -> 0 | K15: =IFERROR(K14/K12,0) -> 0 | ... AD15: =IFERROR(AD14/AD12,0) -> 0 | AF15: =IFERROR(AF14/AF12,0) -> 0.67
AH16: LOM volumes
A17: Operations Yield | D17: =IFERROR(D19/D9,0) -> 0.67 | E17: =IFERROR(E19/E9,0) -> 0.67 | F17: =IFERROR(F19/F9,0) -> 0.67 | G17: =IFERROR(G19/G9,0) -> 0.67 | H17: =IFERROR(H19/H9,0) -> 0.67 | I17: =IFERROR(I19/(I9+H9),0) -> 0 | J17: =IFERROR(J19/(J9+I9),0) -> 0 | K17: =IFERROR(K19/K9,0) -> 0 | L17: =IFERROR(L19/L9,0) -> 0 | M17: =IFERROR(M19/M9,0) -> 0 | N17: =IFERROR(N19/N9,0) -> 0 | O17: =IFERROR(O19/O9,0) -> 0 | P17: =IFERROR(P19/P9,0) -> 0 | Q17: =IFERROR(Q19/Q9,0) -> 0 | R17: =IFERROR(R19/R9,0) -> 0 | ... AD17: =IFERROR(AD19/AD9,0) -> 0 | AF17: =IFERROR(AF19/AF9,0) -> 0.67 | AH17: Development metres (km) | AI17: =AF6/1000 -> 49
AH18: Longwall ROM tonnes / Dev Metres | AI18: =(AI17*1000)/AI20 -> 1.8318529
A19: Saleable Production | B19: kt | D19: =D13+D14 -> 3478.2177 | E19: =E13+E14 -> 3794.3029 | F19: =F13+F14 -> 4011.9895 | G19: =G13+G14 -> 3865.0746 | H19: =H13+H14 -> 3514.7746 | I19: =I13+I14 -> 0 | J19: =J13+J14 -> 0 | K19: =K13+K14 -> 0 | ... AD19: =AD13+AD14 -> 0 | AF19: =SUM(C19:AD19) -> 18664.359 | AH19: Development ROM (kt) | AI19: =AF7 -> 1108.38
AH20: Longwall ROM (kt) | AI20: =AF8 -> 26748.873
A21: Carbon | AH21: Total ROM (kt) | AI21: =AI19+AI20 -> 27857.253
A22: Coal Mine Waste Gass | B22: t CO2e | C22: 0.12 | D22: =IF(D9>0,D9*1000*$C$22+20000,0) -> 642964.37 | E22: =IF(E9>0,E9*1000*$C$22+20000,0) -> 699576.64 | F22: =IF(F9>0,F9*1000*$C$22+20000,0) -> 738565.28 | G22: =IF(G9>0,G9*1000*$C$22+20000,0) -> 712252.16 | H22: =IF(H9>0,H9*1000*$C$22+20000,0) -> 649511.87 | I22: =IF(I9>0,I9*1000*$C$22+20000,0) -> 0 | J22: =IF(J9>0,J9*1000*$C$22+20000,0) -> 0 | K22: =IF(K9>0,K9*1000*$C$22+20000,0) -> 0 | ... AD22: =IF(AD9>0,AD9*1000*$C$22+20000,0) -> 0 | AF22: =SUM(D22:AD22) -> 3442870.3
A23: Decomission Mines Emissions | B23: t CO2e | C23: Look @ Decom Mines Tab | D23: =IF('Decommissioned Mine'!$B$5="Springbok",'Decommissioned Mine'!E2,IF('Decommissioned Mine'!$B$5="Springbok + Brave Blossom",0,IF('Decommissioned Mine'!$B$5="Springbok Delayed 12 Months",'Decommissioned Mine'!E2,0))) -> 0 | E23: =IF('Decommissioned Mine'!$B$5="Springbok",'Decommissioned Mine'!F2,IF('Decommissioned Mine'!$B$5="Springbok + Brave Blossom",0,IF('Decommissioned Mine'!$B$5="Springbok Delayed 12 Months",'Decommissioned Mine'!F2,0))) -> 0 | F23: =IF('Decommissioned Mine'!$B$5="Springbok",'Decommissioned Mine'!G2,IF('Decommissioned Mine'!$B$5="Springbok + Brave Blossom",0,IF('Decommissioned Mine'!$B$5="Springbok Delayed 12 Months",'Decommissioned Mine'!G2,0))) -> 0 | G23: =IF('Decommissioned Mine'!$B$5="Springbok",'Decommissioned Mine'!H2,IF('Decommissioned Mine'!$B$5="Springbok + Brave Blossom",0,IF('Decommissioned Mine'!$B$5="Springbok Delayed 12 Months",'Decommissioned Mine'!H2,0))) -> 0 | H23: =IF('Decommissioned Mine'!$B$5="Springbok",'Decommissioned Mine'!I2,IF('Decommissioned Mine'!$B$5="Springbok + Brave Blossom",0,IF('Decommissioned Mine'!$B$5="Springbok Delayed 12 Months",'Decommissioned Mine'!I2,0))) -> 0 | I23: =IF('Decommissioned Mine'!$B$5="Springbok",'Decommissioned Mine'!J2,IF('Decommissioned Mine'!$B$5="Springbok + Brave Blossom",0,IF('Decommissioned Mine'!$B$5="Springbok Delayed 12 Months",'Decommissioned Mine'!J2,0))) -> 0 | J23: =IF('Decommissioned Mine'!$B$5="Springbok",'Decommissioned Mine'!K2,IF('Decommissioned Mine'!$B$5="Springbok + Brave Blossom",0,IF('Decommissioned Mine'!$B$5="Springbok Delayed 12 Months",'Decommissioned Mine'!K2,0))) -> 0 | K23: =IF('Decommissioned Mine'!$B$5="Springbok",'Decommissioned Mine'!L2,IF('Decommissioned Mine'!$B$5="Springbok + Brave Blossom",0,IF('Decommissioned Mine'!$B$5="Springbok Delayed 12 Months",'Decommissioned Mine'!L2,0))) -> 0 | ... AD23: =IF('Decommissioned Mine'!$B$5="Springbok",'Decommissioned Mine'!AE2,IF('Decommissioned Mine'!$B$5="Springbok + Brave Blossom",0,IF('Decommissioned Mine'!$B$5="Springbok Delayed 12 Months",'Decommissioned Mine'!AE2,0))) -> 0 | AF23: =SUM(D23:AD23) -> 0 | AH23: Remaining Mine Life | AI23: 5
A24: Total Scope 1 Emissions | B24: t CO2e | D24: =D23+D22 -> 642964.37 | E24: =E23+E22 -> 699576.64 | F24: =F23+F22 -> 738565.28 | G24: =G23+G22 -> 712252.16 | H24: =H23+H22 -> 649511.87 | I24: =I23+I22 -> 0 | J24: =J23+J22 -> 0 | K24: =K23+K22 -> 0 | ... AD24: =AD23+AD22 -> 0 | AF24: =SUM(D24:AD24) -> 3442870.3
A25: Safeguard - Hybrid Declining Baseline | B25: t CO2e | D25: =(D9*1000*'Decommissioned Mine'!E22)+'Decommissioned Mine'!E21*D23 -> 426048.29 | E25: =(E9*1000*'Decommissioned Mine'!F22)+'Decommissioned Mine'!F21*E23 -> 413564.91 | F25: =(F9*1000*'Decommissioned Mine'!G22)+'Decommissioned Mine'!G21*F23 -> 386275.6 | G25: =(G9*1000*'Decommissioned Mine'!H22)+'Decommissioned Mine'!H21*G23 -> 339600.7 | H25: =(H9*1000*'Decommissioned Mine'!I22)+'Decommissioned Mine'!I21*H23 -> 292984.94 | I25: =(I9*1000*'Decommissioned Mine'!J22)+'Decommissioned Mine'!J21*I23 -> 0 | J25: =(J9*1000*'Decommissioned Mine'!K22)+'Decommissioned Mine'!K21*J23 -> 0 | K25: =(K9*1000*'Decommissioned Mine'!L22)+'Decommissioned Mine'!L21*K23 -> 0 | ... AD25: =(AD9*1000*'Decommissioned Mine'!AE22)+'Decommissioned Mine'!AE21*AD23 -> 0
A26: Emissions above (or below) baseline | B26: t CO2e | D26: =D24-D25 -> 216916.08 | E26: =E24-E25 -> 286011.72 | F26: =F24-F25 -> 352289.68 | G26: =G24-G25 -> 372651.47 | H26: =H24-H25 -> 356526.93 | I26: =I24-I25 -> 0 | J26: =J24-J25 -> 0 | K26: =K24-K25 -> 0 | ... AD26: =AD24-AD25 -> 0
AE27: =AE23/1000 -> 0
A28: Marketing
A30: Sales
A31: PHCC | B31: kt | D31: =D19 -> 3478.2177 | E31: =E19 -> 3794.3029 | F31: =F19 -> 4011.9895 | G31: =G19 -> 3865.0746 | H31: =H19 -> 3514.7746 | I31: =I19 -> 0 | J31: =J19 -> 0 | K31: =K19 -> 0 | ... AD31: =AD19 -> 0 | AF31: =SUM(C31:AD31) -> 18664.359
A32: 88% PHCC | B32: kt | D32: 0 | E32: 0 | F32: 0 | G32: 0 | H32: 0 | I32: 0 | J32: 0 | K32: 0 | L32: 0 | M32: 0 | N32: 0 | O32: 0 | P32: 0 | Q32: 0 | R32: 0 | S32: 0 | T32: 0 | U32: 0 | V32: 0 | W32: 0 | X32: 0 | Y32: 0 | Z32: 0 | AA32: 0 | AB32: 0 | AC32: 0 | AD32: 0 | AF32: =SUM(C32:AD32) -> 0
A33: Thermal GCN | B33: kt | D33: 0 | E33: 0 | F33: 0 | G33: 0 | H33: 0 | I33: 0 | J33: 0 | K33: 0 | L33: 0 | M33: 0 | N33: 0 | O33: 0 | P33: 0 | Q33: 0 | R33: 0 | S33: 0 | T33: 0 | U33: 0 | V33: 0 | W33: 0 | X33: 0 | Y33: 0 | Z33: 0 | AA33: 0 | AB33: 0 | AC33: 0 | AD33: 0 | AF33: =SUM(C33:AD33) -> 0
A34: Total Sales | B34: kt | D34: =SUM(D31:D33) -> 3478.2177 | E34: =SUM(E31:E33) -> 3794.3029 | F34: =SUM(F31:F33) -> 4011.9895 | G34: =SUM(G31:G33) -> 3865.0746 | H34: =SUM(H31:H33) -> 3514.7746 | I34: =SUM(I31:I33) -> 0 | J34: =SUM(J31:J33) -> 0 | K34: =SUM(K31:K33) -> 0 | ... AD34: =SUM(AD31:AD33) -> 0 | AE34: =SUM(AE31:AE32) -> 0 | AF34: =SUM(AF31:AF32) -> 18664.359
A36: Product Ash (as received)
